Workbook

Sheet Ответы на форму (1)
A1: Отметка времени | B1: Вопрос без заголовка

Sheet Общий зачет
A1: =SUM(C2:I34)-'все бани'!C1-SUM('все бани'!D2:AJ7) -> 0 | B1: Итого | C1: К-во | D1: У | E1: УУ | F1: Дл | G1: К | H1: Общ | I1: Рег | J1: W8 | K1: W7 | L1: W6 | M1: W5 | N1: W4 | O1: W3 | P1: W2 | Q1: W1
A2: Леха | B2: =SUM(C2:Q2) -> 172.85 | C2: =VLOOKUP(A2,'недельный зачет'!$A:$B,2,FALSE) -> 30 | D2: =HLOOKUP(A2,'все бани'!$1:$7,7,FALSE) -> 17 | E2: =HLOOKUP(A2,'все бани'!$1:$7,6,FALSE) -> 13 | F2: =HLOOKUP(A2,'все бани'!$1:$7,5,FALSE) -> 13 | G2: =HLOOKUP(A2,'все бани'!$1:$7,2,FALSE) -> 13 | H2: =HLOOKUP(A2,'все бани'!$1:$7,4,FALSE) -> 14 | I2: =HLOOKUP(A2,'все бани'!$1:$7,3,FALSE) -> 11 | J2: 8 | K2: =45/4 -> 11.25 | L2: 10 | M2: 8 | N2: 0 | O2: 12 | P2: 12 | Q2: =3/5 -> 0.6
A3: Шурик | B3: =SUM(C3:Q3) -> 142.35278 | C3: =VLOOKUP(A3,'недельный зачет'!$A:$B,2,FALSE) -> 20 | D3: =HLOOKUP(A3,'все бани'!$1:$7,7,FALSE) -> 20 | E3: =HLOOKUP(A3,'все бани'!$1:$7,6,FALSE) -> 18 | F3: =HLOOKUP(A3,'все бани'!$1:$7,5,FALSE) -> 8 | G3: =HLOOKUP(A3,'все бани'!$1:$7,2,FALSE) -> 9 | H3: =HLOOKUP(A3,'все бани'!$1:$7,4,FALSE) -> 14 | I3: =HLOOKUP(A3,'все бани'!$1:$7,3,FALSE) -> 17 | J3: =3/8 -> 0.375 | K3: 6 | L3: 0 | M3: =7/10 -> 0.7 | N3: 0 | O3: =7/9 -> 0.77777778 | P3: 15 | Q3: 13.5
A4: Витёк | B4: =SUM(C4:Q4) -> 148.31111 | C4: =VLOOKUP(A4,'недельный зачет'!$A:$B,2,FALSE) -> 24 | D4: =HLOOKUP(A4,'все бани'!$1:$7,7,FALSE) -> 18 | E4: =HLOOKUP(A4,'все бани'!$1:$7,6,FALSE) -> 9 | F4: =HLOOKUP(A4,'все бани'!$1:$7,5,FALSE) -> 13 | G4: =HLOOKUP(A4,'все бани'!$1:$7,2,FALSE) -> 16 | H4: =HLOOKUP(A4,'все бани'!$1:$7,4,FALSE) -> 13 | I4: =HLOOKUP(A4,'все бани'!$1:$7,3,FALSE) -> 7 | J4: 8 | K4: =45/4 -> 11.25 | L4: =1/4 -> 0.25 | M4: =7/10 -> 0.7 | N4: =37/3 -> 12.333333 | O4: =7/9 -> 0.77777778 | P4: 8 | Q4: 7
A5: Денис | B5: =SUM(C5:Q5) -> 137.93333 | C5: =VLOOKUP(A5,'недельный зачет'!$A:$B,2,FALSE) -> 34 | D5: =HLOOKUP(A5,'все бани'!$1:$7,7,FALSE) -> 7 | E5: =HLOOKUP(A5,'все бани'!$1:$7,6,FALSE) -> 3 | F5: =HLOOKUP(A5,'все бани'!$1:$7,5,FALSE) -> 2 | G5: =HLOOKUP(A5,'все бани'!$1:$7,2,FALSE) -> 0 | H5: =HLOOKUP(A5,'все бани'!$1:$7,4,FALSE) -> 1 | I5: =HLOOKUP(A5,'все бани'!$1:$7,3,FALSE) -> 5 | J5: 15 | K5: =45/4 -> 11.25 | L5: 13.5 | M5: 15 | N5: =37/3 -> 12.333333 | O5: 15 | P5: =13/4 -> 3.25 | Q5: =3/5 -> 0.6
A6: Женёк В | B6: =SUM(C6:Q6) -> 126.66414 | C6: =VLOOKUP(A6,'недельный зачет'!$A:$B,2,FALSE) -> 20 | D6: =HLOOKUP(A6,'все бани'!$1:$7,7,FALSE) -> 17 | E6: =HLOOKUP(A6,'все бани'!$1:$7,6,FALSE) -> 8 | F6: =HLOOKUP(A6,'все бани'!$1:$7,5,FALSE) -> 7 | G6: =HLOOKUP(A6,'все бани'!$1:$7,2,FALSE) -> 9 | H6: =HLOOKUP(A6,'все бани'!$1:$7,4,FALSE) -> 12 | I6: =HLOOKUP(A6,'все бани'!$1:$7,3,FALSE) -> 11 | J6: 0 | K6: =45/4 -> 11.25 | L6: 5 | M6: 8 | N6: =7/11 -> 0.63636364 | O6: =7/9 -> 0.77777778 | P6: 10 | Q6: 7
A7: Ден | B7: =SUM(C7:Q7) -> 122.625 | C7: =VLOOKUP(A7,'недельный зачет'!$A:$B,2,FALSE) -> 21 | D7: =HLOOKUP(A7,'все бани'!$1:$7,7,FALSE) -> 10 | E7: =HLOOKUP(A7,'все бани'!$1:$7,6,FALSE) -> 0 | F7: =HLOOKUP(A7,'все бани'!$1:$7,5,FALSE) -> 13 | G7: =HLOOKUP(A7,'все бани'!$1:$7,2,FALSE) -> 8 | H7: =HLOOKUP(A7,'все бани'!$1:$7,4,FALSE) -> 15 | I7: =HLOOKUP(A7,'все бани'!$1:$7,3,FALSE) -> 3 | J7: 0 | K7: =7/8 -> 0.875 | L7: 13.5 | M7: 12 | N7: 6 | O7: 10 | P7: =13/4 -> 3.25 | Q7: 7
A8: Диман | B8: =SUM(C8:Q8) -> 90.908333 | C8: =VLOOKUP(A8,'недельный зачет'!$A:$B,2,FALSE) -> 13 | D8: =HLOOKUP(A8,'все бани'!$1:$7,7,FALSE) -> 12 | E8: =HLOOKUP(A8,'все бани'!$1:$7,6,FALSE) -> 2 | F8: =HLOOKUP(A8,'все бани'!$1:$7,5,FALSE) -> 10 | G8: =HLOOKUP(A8,'все бани'!$1:$7,2,FALSE) -> 12 | H8: =HLOOKUP(A8,'все бани'!$1:$7,4,FALSE) -> 11 | I8: =HLOOKUP(A8,'все бани'!$1:$7,3,FALSE) -> 4 | J8: 8 | K8: =7/8 -> 0.875 | L8: 5 | M8: =7/10 -> 0.7 | N8: =37/3 -> 12.333333 | O8: 0 | P8: 0 | Q8: 0
A9: Арс | B9: =SUM(C9:Q9) -> 70.739141 | C9: =VLOOKUP(A9,'недельный зачет'!$A:$B,2,FALSE) -> 13 | D9: =HLOOKUP(A9,'все бани'!$1:$7,7,FALSE) -> 9 | E9: =HLOOKUP(A9,'все бани'!$1:$7,6,FALSE) -> 1 | F9: =HLOOKUP(A9,'все бани'!$1:$7,5,FALSE) -> 12 | G9: =HLOOKUP(A9,'все бани'!$1:$7,2,FALSE) -> 6 | H9: =HLOOKUP(A9,'все бани'!$1:$7,4,FALSE) -> 7 | I9: =HLOOKUP(A9,'все бани'!$1:$7,3,FALSE) -> 5 | J9: =3/8 -> 0.375 | K9: 0 | L9: 5 | M9: =7/10 -> 0.7 | N9: =7/11 -> 0.63636364 | O9: =7/9 -> 0.77777778 | P9: =13/4 -> 3.25 | Q9: 7
A10: Фил | B10: =SUM(C10:Q10) -> 66.852778 | C10: =VLOOKUP(A10,'недельный зачет'!$A:$B,2,FALSE) -> 11 | D10: =HLOOKUP(A10,'все бани'!$1:$7,7,FALSE) -> 11 | E10: =HLOOKUP(A10,'все бани'!$1:$7,6,FALSE) -> 3 | F10: =HLOOKUP(A10,'все бани'!$1:$7,5,FALSE) -> 7 | G10: =HLOOKUP(A10,'все бани'!$1:$7,2,FALSE) -> 11 | H10: =HLOOKUP(A10,'все бани'!$1:$7,4,FALSE) -> 11 | I10: =HLOOKUP(A10,'все бани'!$1:$7,3,FALSE) -> 3 | J10: =3/8 -> 0.375 | K10: 0 | L10: 0 | M10: =7/10 -> 0.7 | N10: 8 | O10: =7/9 -> 0.77777778 | P10: 0 | Q10: 0
A11: san4ony | B11: =SUM(C11:Q11) -> 56.589141 | C11: =VLOOKUP(A11,'недельный зачет'!$A:$B,2,FALSE) -> 12 | D11: =HLOOKUP(A11,'все бани'!$1:$7,7,FALSE) -> 6 | E11: =HLOOKUP(A11,'все бани'!$1:$7,6,FALSE) -> 5 | F11: =HLOOKUP(A11,'все бани'!$1:$7,5,FALSE) -> 10 | G11: =HLOOKUP(A11,'все бани'!$1:$7,2,FALSE) -> 2 | H11: =HLOOKUP(A11,'все бани'!$1:$7,4,FALSE) -> 9 | I11: =HLOOKUP(A11,'все бани'!$1:$7,3,FALSE) -> 4 | J11: 0 | K11: =7/8 -> 0.875 | L11: 5 | M11: =7/10 -> 0.7 | N11: =7/11 -> 0.63636364 | O11: =7/9 -> 0.77777778 | P11: 0 | Q11: =3/5 -> 0.6
A12: Хвост | B12: =SUM(C12:Q12) -> 46.375 | C12: =VLOOKUP(A12,'недельный зачет'!$A:$B,2,FALSE) -> 8 | D12: =HLOOKUP(A12,'все бани'!$1:$7,7,FALSE) -> 7 | E12: =HLOOKUP(A12,'все бани'!$1:$7,6,FALSE) -> 1 | F12: =HLOOKUP(A12,'все бани'!$1:$7,5,FALSE) -> 6 | G12: =HLOOKUP(A12,'все бани'!$1:$7,2,FALSE) -> 5 | H12: =HLOOKUP(A12,'все бани'!$1:$7,4,FALSE) -> 5 | I12: =HLOOKUP(A12,'все бани'!$1:$7,3,FALSE) -> 3 | J12: 0 | K12: =7/8 -> 0.875 | L12: =1/4 -> 0.25 | M12: 0 | N12: 0 | O12: 7 | P12: =13/4 -> 3.25 | Q12: 0
A13: Миша П | B13: =SUM(C13:Q13) -> 41.902778 | C13: =VLOOKUP(A13,'недельный зачет'!$A:$B,2,FALSE) -> 9 | D13: =HLOOKUP(A13,'все бани'!$1:$7,7,FALSE) -> 6 | E13: =HLOOKUP(A13,'все бани'!$1:$7,6,FALSE) -> 2 | F13: =HLOOKUP(A13,'все бани'!$1:$7,5,FALSE) -> 2 | G13: =HLOOKUP(A13,'все бани'!$1:$7,2,FALSE) -> 0 | H13: =HLOOKUP(A13,'все бани'!$1:$7,4,FALSE) -> 2 | I13: =HLOOKUP(A13,'все бани'!$1:$7,3,FALSE) -> 3 | J13: 8 | K13: =7/8 -> 0.875 | L13: =1/4 -> 0.25 | M13: 8 | N13: 0 | O13: =7/9 -> 0.77777778 | P13: 0 | Q13: 0
A14: Данюс | B14: =SUM(C14:Q14) -> 32.664141 | C14: =VLOOKUP(A14,'недельный зачет'!$A:$B,2,FALSE) -> 7 | D14: =HLOOKUP(A14,'все бани'!$1:$7,7,FALSE) -> 4 | E14: =HLOOKUP(A14,'все бани'!$1:$7,6,FALSE) -> 1 | F14: =HLOOKUP(A14,'все бани'!$1:$7,5,FALSE) -> 6 | G14: =HLOOKUP(A14,'все бани'!$1:$7,2,FALSE) -> 0 | H14: =HLOOKUP(A14,'все бани'!$1:$7,4,FALSE) -> 3 | I14: =HLOOKUP(A14,'все бани'!$1:$7,3,FALSE) -> 2 | J14: 8 | K14: 0 | L14: =1/4 -> 0.25 | M14: 0 | N14: =7/11 -> 0.63636364 | O14: =7/9 -> 0.77777778 | P14: 0 | Q14: 0
A15: Ахмед | B15: =SUM(C15:Q15) -> 27.55 | C15: =VLOOKUP(A15,'недельный зачет'!$A:$B,2,FALSE) -> 6 | D15: =HLOOKUP(A15,'все бани'!$1:$7,7,FALSE) -> 4 | E15: =HLOOKUP(A15,'все бани'!$1:$7,6,FALSE) -> 1 | F15: =HLOOKUP(A15,'все бани'!$1:$7,5,FALSE) -> 5 | G15: =HLOOKUP(A15,'все бани'!$1:$7,2,FALSE) -> 0 | H15: =HLOOKUP(A15,'все бани'!$1:$7,4,FALSE) -> 5 | I15: =HLOOKUP(A15,'все бани'!$1:$7,3,FALSE) -> 4 | J15: =3/8 -> 0.375 | K15: =7/8 -> 0.875 | L15: 0 | M15: =7/10 -> 0.7 | N15: 0 | O15: 0 | P15: 0 | Q15: =3/5 -> 0.6
A16: Даня | B16: =SUM(C16:Q16) -> 25.636364 | C16: =VLOOKUP(A16,'недельный зачет'!$A:$B,2,FALSE) -> 4 | D16: =HLOOKUP(A16,'все бани'!$1:$7,7,FALSE) -> 3 | E16: =HLOOKUP(A16,'все бани'!$1:$7,6,FALSE) -> 1 | F16: =HLOOKUP(A16,'все бани'!$1:$7,5,FALSE) -> 2 | G16: =HLOOKUP(A16,'все бани'!$1:$7,2,FALSE) -> 4 | H16: =HLOOKUP(A16,'все бани'!$1:$7,4,FALSE) -> 1 | I16: =HLOOKUP(A16,'все бани'!$1:$7,3,FALSE) -> 3 | J16: 0 | K16: 0 | L16: 0 | M16: 0 | N16: =7/11 -> 0.63636364 | O16: 7 | P16: 0 | Q16: 0
A17: Симба | B17: =SUM(C17:Q17) -> 25.277778 | C17: =VLOOKUP(A17,'недельный зачет'!$A:$B,2,FALSE) -> 3 | D17: =HLOOKUP(A17,'все бани'!$1:$7,7,FALSE) -> 2 | E17: =HLOOKUP(A17,'все бани'!$1:$7,6,FALSE) -> 1 | F17: =HLOOKUP(A17,'все бани'!$1:$7,5,FALSE) -> 1 | G17: =HLOOKUP(A17,'все бани'!$1:$7,2,FALSE) -> 2 | H17: =HLOOKUP(A17,'все бани'!$1:$7,4,FALSE) -> 0 | I17: =HLOOKUP(A17,'все бани'!$1:$7,3,FALSE) -> 2 | J17: 0 | K17: 0 | L17: 0 | M17: 0 | N17: 0 | O17: =7/9 -> 0.77777778 | P17: 0 | Q17: 13.5
A18: Alex B | B18: =SUM(C18:Q18) -> 29.211364 | C18: =VLOOKUP(A18,'недельный зачет'!$A:$B,2,FALSE) -> 7 | D18: =HLOOKUP(A18,'все бани'!$1:$7,7,FALSE) -> 6 | E18: =HLOOKUP(A18,'все бани'!$1:$7,6,FALSE) -> 1 | F18: =HLOOKUP(A18,'все бани'!$1:$7,5,FALSE) -> 4 | G18: =HLOOKUP(A18,'все бани'!$1:$7,2,FALSE) -> 2 | H18: =HLOOKUP(A18,'все бани'!$1:$7,4,FALSE) -> 4 | I18: =HLOOKUP(A18,'все бани'!$1:$7,3,FALSE) -> 3 | J18: 0 | K18: =7/8 -> 0.875 | L18: 0 | M18: =7/10 -> 0.7 | N18: =7/11 -> 0.63636364 | O18: 0 | P18: 0 | Q18: 0
A19: Махмуд | B19: =SUM(C19:Q19) -> 29.475 | C19: =VLOOKUP(A19,'недельный зачет'!$A:$B,2,FALSE) -> 5 | D19: =HLOOKUP(A19,'все бани'!$1:$7,7,FALSE) -> 5 | E19: =HLOOKUP(A19,'все бани'!$1:$7,6,FALSE) -> 1 | F19: =HLOOKUP(A19,'все бани'!$1:$7,5,FALSE) -> 4 | G19: =HLOOKUP(A19,'все бани'!$1:$7,2,FALSE) -> 6 | H19: =HLOOKUP(A19,'все бани'!$1:$7,4,FALSE) -> 4 | I19: =HLOOKUP(A19,'все бани'!$1:$7,3,FALSE) -> 3 | J19: 0 | K19: =7/8 -> 0.875 | L19: 0 | M19: 0 | N19: 0 | O19: 0 | P19: 0 | Q19: =3/5 -> 0.6
A20: Толмач | B20: =SUM(C20:Q20) -> 18.789141 | C20: =VLOOKUP(A20,'недельный зачет'!$A:$B,2,FALSE) -> 4 | D20: =HLOOKUP(A20,'все бани'!$1:$7,7,FALSE) -> 4 | E20: =HLOOKUP(A20,'все бани'!$1:$7,6,FALSE) -> 2 | F20: =HLOOKUP(A20,'все бани'!$1:$7,5,FALSE) -> 1 | G20: =HLOOKUP(A20,'все бани'!$1:$7,2,FALSE) -> 1 | H20: =HLOOKUP(A20,'все бани'!$1:$7,4,FALSE) -> 1 | I20: =HLOOKUP(A20,'все бани'!$1:$7,3,FALSE) -> 4 | J20: =3/8 -> 0.375 | K20: 0 | L20: 0 | M20: 0 | N20: =7/11 -> 0.63636364 | O20: =7/9 -> 0.77777778 | P20: 0 | Q20: 0
A21: Макс | B21: =SUM(C21:Q21) -> 17.636364 | C21: =VLOOKUP(A21,'недельный зачет'!$A:$B,2,FALSE) -> 3 | D21: =HLOOKUP(A21,'все бани'!$1:$7,7,FALSE) -> 3 | E21: =HLOOKUP(A21,'все бани'!$1:$7,6,FALSE) -> 0 | F21: =HLOOKUP(A21,'все бани'!$1:$7,5,FALSE) -> 2 | G21: =HLOOKUP(A21,'все бани'!$1:$7,2,FALSE) -> 5 | H21: =HLOOKUP(A21,'все бани'!$1:$7,4,FALSE) -> 1 | I21: =HLOOKUP(A21,'все бани'!$1:$7,3,FALSE) -> 3 | J21: 0 | K21: 0 | L21: 0 | M21: 0 | N21: =7/11 -> 0.63636364 | O21: 0 | P21: 0 | Q21: 0
A22: Жанат | B22: =SUM(C22:Q22) -> 13.636364 | C22: =VLOOKUP(A22,'недельный зачет'!$A:$B,2,FALSE) -> 2 | D22: =HLOOKUP(A22,'все бани'!$1:$7,7,FALSE) -> 2 | E22: =HLOOKUP(A22,'все бани'!$1:$7,6,FALSE) -> 0 | F22: =HLOOKUP(A22,'все бани'!$1:$7,5,FALSE) -> 2 | G22: =HLOOKUP(A22,'все бани'!$1:$7,2,FALSE) -> 4 | H22: =HLOOKUP(A22,'все бани'!$1:$7,4,FALSE) -> 1 | I22: =HLOOKUP(A22,'все бани'!$1:$7,3,FALSE) -> 2 | J22: 0 | K22: 0 | L22: 0 | M22: 0 | N22: =7/11 -> 0.63636364 | O22: 0 | P22: 0 | Q22: 0
A23: Женёк З | B23: =SUM(C23:Q23) -> 13.011364 | C23: =VLOOKUP(A23,'недельный зачет'!$A:$B,2,FALSE) -> 2 | D23: =HLOOKUP(A23,'все бани'!$1:$7,7,FALSE) -> 2 | E23: =HLOOKUP(A23,'все бани'!$1:$7,6,FALSE) -> 1 | F23: =HLOOKUP(A23,'все бани'!$1:$7,5,FALSE) -> 1 | G23: =HLOOKUP(A23,'все бани'!$1:$7,2,FALSE) -> 1 | H23: =HLOOKUP(A23,'все бани'!$1:$7,4,FALSE) -> 1 | I23: =HLOOKUP(A23,'все бани'!$1:$7,3,FALSE) -> 4 | J23: =3/8 -> 0.375 | K23: 0 | L23: 0 | M23: 0 | N23: =7/11 -> 0.63636364 | O23: 0 | P23: 0 | Q23: 0
A24: Леха С | B24: =SUM(C24:Q24) -> 11.075 | C24: =VLOOKUP(A24,'недельный зачет'!$A:$B,2,FALSE) -> 2 | D24: =HLOOKUP(A24,'все бани'!$1:$7,7,FALSE) -> 2 | E24: =HLOOKUP(A24,'все бани'!$1:$7,6,FALSE) -> 2 | F24: =HLOOKUP(A24,'все бани'!$1:$7,5,FALSE) -> 1 | G24: =HLOOKUP(A24,'все бани'!$1:$7,2,FALSE) -> 0 | H24: =HLOOKUP(A24,'все бани'!$1:$7,4,FALSE) -> 0 | I24: =HLOOKUP(A24,'все бани'!$1:$7,3,FALSE) -> 3 | J24: =3/8 -> 0.375 | K24: 0 | L24: 0 | M24: =7/10 -> 0.7 | N24: 0 | O24: 0 | P24: 0 | Q24: 0
A25: Вадик | B25: =SUM(C25:Q25) -> 9.6363636 | C25: =VLOOKUP(A25,'недельный зачет'!$A:$B,2,FALSE) -> 1 | D25: =HLOOKUP(A25,'все бани'!$1:$7,7,FALSE) -> 1 | E25: =HLOOKUP(A25,'все бани'!$1:$7,6,FALSE) -> 0 | F25: =HLOOKUP(A25,'все бани'!$1:$7,5,FALSE) -> 1 | G25: =HLOOKUP(A25,'все бани'!$1:$7,2,FALSE) -> 3 | H25: =HLOOKUP(A25,'все бани'!$1:$7,4,FALSE) -> 1 | I25: =HLOOKUP(A25,'все бани'!$1:$7,3,FALSE) -> 2 | J25: 0 | K25: 0 | L25: 0 | M25: 0 | N25: =7/11 -> 0.63636364 | O25: 0 | P25: 0 | Q25: 0
A26: Дёс | B26: =SUM(C26:Q26) -> 12 | C26: =VLOOKUP(A26,'недельный зачет'!$A:$B,2,FALSE) -> 2 | D26: =HLOOKUP(A26,'все бани'!$1:$7,7,FALSE) -> 2 | E26: =HLOOKUP(A26,'все бани'!$1:$7,6,FALSE) -> 0 | F26: =HLOOKUP(A26,'все бани'!$1:$7,5,FALSE) -> 2 | G26: =HLOOKUP(A26,'все бани'!$1:$7,2,FALSE) -> 2 | H26: =HLOOKUP(A26,'все бани'!$1:$7,4,FALSE) -> 2 | I26: =HLOOKUP(A26,'все бани'!$1:$7,3,FALSE) -> 2 | J26: 0 | K26: 0 | L26: 0 | M26: 0 | N26: 0 | O26: 0 | P26: 0 | Q26: 0
A27: Чен | B27: =SUM(C27:Q27) -> 6.7 | C27: =VLOOKUP(A27,'недельный зачет'!$A:$B,2,FALSE) -> 1 | D27: =HLOOKUP(A27,'все бани'!$1:$7,7,FALSE) -> 1 | E27: =HLOOKUP(A27,'все бани'!$1:$7,6,FALSE) -> 1 | F27: =HLOOKUP(A27,'все бани'!$1:$7,5,FALSE) -> 0 | G27: =HLOOKUP(A27,'все бани'!$1:$7,2,FALSE) -> 0 | H27: =HLOOKUP(A27,'все бани'!$1:$7,4,FALSE) -> 1 | I27: =HLOOKUP(A27,'все бани'!$1:$7,3,FALSE) -> 2 | J27: 0 | K27: 0 | L27: 0 | M27: =7/10 -> 0.7 | N27: 0 | O27: 0 | P27: 0 | Q27: 0
A28: Пашок | B28: =SUM(C28:Q28) -> 6.375 | C28: =VLOOKUP(A28,'недельный зачет'!$A:$B,2,FALSE) -> 1 | D28: =HLOOKUP(A28,'все бани'!$1:$7,7,FALSE) -> 1 | E28: =HLOOKUP(A28,'все бани'!$1:$7,6,FALSE) -> 1 | F28: =HLOOKUP(A28,'все бани'!$1:$7,5,FALSE) -> 0 | G28: =HLOOKUP(A28,'все бани'!$1:$7,2,FALSE) -> 1 | H28: =HLOOKUP(A28,'все бани'!$1:$7,4,FALSE) -> 0 | I28: =HLOOKUP(A28,'все бани'!$1:$7,3,FALSE) -> 2 | J28: =3/8 -> 0.375 | K28: 0 | L28: 0 | M28: 0 | N28: 0 | O28: 0 | P28: 0 | Q28: 0
A29: Костян | B29: =SUM(C29:Q29) -> 6 | C29: =VLOOKUP(A29,'недельный зачет'!$A:$B,2,FALSE) -> 1 | D29: =HLOOKUP(A29,'все бани'!$1:$7,7,FALSE) -> 1 | E29: =HLOOKUP(A29,'все бани'!$1:$7,6,FALSE) -> 0 | F29: =HLOOKUP(A29,'все бани'!$1:$7,5,FALSE) -> 1 | G29: =HLOOKUP(A29,'все бани'!$1:$7,2,FALSE) -> 1 | H29: =HLOOKUP(A29,'все бани'!$1:$7,4,FALSE) -> 0 | I29: =HLOOKUP(A29,'все бани'!$1:$7,3,FALSE) -> 2 | J29: 0 | K29: 0 | L29: 0 | M29: 0 | N29: 0 | O29: 0 | P29: 0 | Q29: 0
A30: Король | B30: =SUM(C30:Q30) -> 6 | C30: =VLOOKUP(A30,'недельный зачет'!$A:$B,2,FALSE) -> 1 | D30: =HLOOKUP(A30,'все бани'!$1:$7,7,FALSE) -> 1 | E30: =HLOOKUP(A30,'все бани'!$1:$7,6,FALSE) -> 0 | F30: =HLOOKUP(A30,'все бани'!$1:$7,5,FALSE) -> 1 | G30: =HLOOKUP(A30,'все бани'!$1:$7,2,FALSE) -> 0 | H30: =HLOOKUP(A30,'все бани'!$1:$7,4,FALSE) -> 1 | I30: =HLOOKUP(A30,'все бани'!$1:$7,3,FALSE) -> 2 | J30: 0 | K30: 0 | L30: 0 | M30: 0 | N30: 0 | O30: 0 | P30: 0 | Q30: 0
A31: Серёга | B31: =SUM(C31:Q31) -> 0 | C31: =VLOOKUP(A31,'недельный зачет'!$A:$B,2,FALSE) -> 0 | D31: =HLOOKUP(A31,'все бани'!$1:$7,7,FALSE) -> 0 | E31: =HLOOKUP(A31,'все бани'!$1:$7,6,FALSE) -> 0 | F31: =HLOOKUP(A31,'все бани'!$1:$7,5,FALSE) -> 0 | G31: =HLOOKUP(A31,'все бани'!$1:$7,2,FALSE) -> 0 | H31: =HLOOKUP(A31,'все бани'!$1:$7,4,FALSE) -> 0 | I31: =HLOOKUP(A31,'все бани'!$1:$7,3,FALSE) -> 0 | J31: 0 | K31: 0 | L31: 0 | M31: 0 | N31: 0 | O31: 0 | P31: 0 | Q31: 0
A32: Саня С | B32: =SUM(C32:Q32) -> 0 | C32: =VLOOKUP(A32,'недельный зачет'!$A:$B,2,FALSE) -> 0 | D32: =HLOOKUP(A32,'все бани'!$1:$7,7,FALSE) -> 0 | E32: =HLOOKUP(A32,'все бани'!$1:$7,6,FALSE) -> 0 | F32: =HLOOKUP(A32,'все бани'!$1:$7,5,FALSE) -> 0 | G32: =HLOOKUP(A32,'все бани'!$1:$7,2,FALSE) -> 0 | H32: =HLOOKUP(A32,'все бани'!$1:$7,4,FALSE) -> 0 | I32: =HLOOKUP(A32,'все бани'!$1:$7,3,FALSE) -> 0 | J32: 0 | K32: 0 | L32: 0 | M32: 0 | N32: 0 | O32: 0 | P32: 0 | Q32: 0
A33: Самат | B33: =SUM(C33:Q33) -> 0 | C33: =VLOOKUP(A33,'недельный зачет'!$A:$B,2,FALSE) -> 0 | D33: =HLOOKUP(A33,'все бани'!$1:$7,7,FALSE) -> 0 | E33: =HLOOKUP(A33,'все бани'!$1:$7,6,FALSE) -> 0 | F33: =HLOOKUP(A33,'все бани'!$1:$7,5,FALSE) -> 0 | G33: =HLOOKUP(A33,'все бани'!$1:$7,2,FALSE) -> 0 | H33: =HLOOKUP(A33,'все бани'!$1:$7,4,FALSE) -> 0 | I33: =HLOOKUP(A33,'все бани'!$1:$7,3,FALSE) -> 0 | J33: 0 | K33: 0 | L33: 0 | M33: 0 | N33: 0 | O33: 0 | P33: 0 | Q33: 0
A34: Дор | B34: =SUM(C34:Q34) -> 0 | C34: =VLOOKUP(A34,'недельный зачет'!$A:$B,2,FALSE) -> 0 | D34: =HLOOKUP(A34,'все бани'!$1:$7,7,FALSE) -> 0 | E34: =HLOOKUP(A34,'все бани'!$1:$7,6,FALSE) -> 0 | F34: =HLOOKUP(A34,'все бани'!$1:$7,5,FALSE) -> 0 | G34: =HLOOKUP(A34,'все бани'!$1:$7,2,FALSE) -> 0 | H34: =HLOOKUP(A34,'все бани'!$1:$7,4,FALSE) -> 0 | I34: =HLOOKUP(A34,'все бани'!$1:$7,3,FALSE) -> 0 | J34: 0 | K34: 0 | L34: 0 | M34: 0 | N34: 0 | O34: 0 | P34: 0 | Q34: 0

Sheet недельный зачет
B1: =SUM(B3:B191) -> 267 | C1: =SUM(C3:C191) -> 35 | D1: =SUM(D3:D191) -> 22 | E1: =SUM(E3:E191) -> 22 | F1: =SUM(F3:F191) -> 23 | G1: =SUM(G3:G191) -> 23 | H1: =SUM(H3:H191) -> 28 | I1: =SUM(I3:I191) -> 28 | ... K1: =SUM(K3:K191) -> 19
B2: Всего | C2: W9 | D2: W8 | E2: W7 | F2: W6 | G2: W5 | H2: W4 | I2: W3 | J2: W2 | K2: W1
A3: Денис | B3: =SUM(C3:K3) -> 34 | C3: 3 | D3: 4 | E3: 3 | F3: 4 | G3: 4 | H3: 4 | I3: 8 | J3: 3 | K3: 1
A4: Леха | B4: =SUM(C4:K4) -> 30 | C4: 4 | D4: 2 | E4: 3 | F4: 3 | G4: 2 | H4: 0 | I4: 4 | J4: 11 | K4: 1
A5: Шурик | B5: =SUM(C5:K5) -> 20 | D5: 1 | E5: 2 | F5: 0 | G5: 1 | H5: 0 | I5: 1 | J5: 12 | K5: 3
A6: Витёк | B6: =SUM(C6:K6) -> 24 | C6: 4 | D6: 2 | E6: 3 | F6: 1 | G6: 1 | H6: 4 | I6: 1 | J6: 6 | K6: 2
A7: Женёк В | B7: =SUM(C7:K7) -> 20 | C7: 1 | D7: 0 | E7: 3 | F7: 2 | G7: 2 | H7: 1 | I7: 1 | J7: 8 | K7: 2
A8: Ден | B8: =SUM(C8:K8) -> 21 | C8: 3 | D8: 0 | E8: 1 | F8: 4 | G8: 3 | H8: 2 | I8: 3 | J8: 3 | K8: 2
A9: Арс | B9: =SUM(C9:K9) -> 13 | C9: 2 | D9: 1 | E9: 0 | F9: 2 | G9: 1 | H9: 1 | I9: 1 | J9: 3 | K9: 2
A10: Диман | B10: =SUM(C10:K10) -> 13 | C10: 3 | D10: 2 | E10: 1 | F10: 2 | G10: 1 | H10: 4 | I10: 0 | J10: 0 | K10: 0
A11: san4ony | B11: =SUM(C11:K11) -> 12 | C11: 3 | D11: 0 | E11: 1 | F11: 2 | G11: 1 | H11: 1 | I11: 1 | J11: 2 | K11: 1
A12: Фил | B12: =SUM(C12:K12) -> 11 | C12: 3 | D12: 1 | E12: 0 | F12: 0 | G12: 1 | H12: 3 | I12: 1 | J12: 2 | K12: 0
A13: Миша П | B13: =SUM(C13:K13) -> 9 | C13: 1 | D13: 2 | E13: 1 | F13: 1 | G13: 2 | H13: 0 | I13: 1 | J13: 1 | K13: 0
A14: Хвост | B14: =SUM(C14:K14) -> 8 | C14: 1 | D14: 0 | E14: 1 | F14: 1 | G14: 0 | H14: 0 | I14: 2 | J14: 3 | K14: 0
A15: Данюс | B15: =SUM(C15:K15) -> 7 | D15: 2 | E15: 0 | F15: 1 | G15: 0 | H15: 1 | I15: 1 | J15: 2 | K15: 0
A16: Ахмед | B16: =SUM(C16:K16) -> 6 | D16: 1 | E16: 1 | F16: 0 | G16: 1 | H16: 0 | I16: 0 | J16: 2 | K16: 1
A17: Alex B | B17: =SUM(C17:K17) -> 7 | C17: 2 | D17: 0 | E17: 1 | F17: 0 | G17: 1 | H17: 1 | I17: 0 | J17: 2 | K17: 0
A18: Даня | B18: =SUM(C18:K18) -> 4 | D18: 0 | E18: 0 | F18: 0 | G18: 0 | H18: 1 | I18: 2 | J18: 1 | K18: 0
A19: Симба | B19: =SUM(C19:K19) -> 3 | D19: 0 | E19: 0 | F19: 0 | G19: 0 | H19: 0 | I19: 0 | J19: 0 | K19: 3
A20: Махмуд | B20: =SUM(C20:K20) -> 5 | C20: 2 | D20: 0 | E20: 1 | F20: 0 | G20: 0 | H20: 0 | I20: 0 | J20: 1 | K20: 1
A21: Толмач | B21: =SUM(C21:K21) -> 4 | C21: 1 | D21: 1 | E21: 0 | F21: 0 | G21: 0 | H21: 1 | I21: 1 | J21: 0 | K21: 0
A22: Жанат | B22: =SUM(C22:K22) -> 2 | D22: 0 | E22: 0 | F22: 0 | G22: 0 | H22: 1 | I22: 0 | J22: 1 | K22: 0
A23: Макс | B23: =SUM(C23:K23) -> 3 | C23: 1 | D23: 0 | E23: 0 | F23: 0 | G23: 0 | H23: 1 | I23: 0 | J23: 1 | K23: 0
A24: Женёк З | B24: =SUM(C24:K24) -> 2 | D24: 1 | E24: 0 | F24: 0 | G24: 0 | H24: 1 | I24: 0 | J24: 0 | K24: 0
A25: Леха С | B25: =SUM(C25:K25) -> 2 | D25: 1 | E25: 0 | F25: 0 | G25: 1 | H25: 0 | I25: 0 | J25: 0 | K25: 0
A26: Король | B26: =SUM(C26:K26) -> 1 | D26: 0 | E26: 0 | F26: 0 | G26: 0 | H26: 0 | I26: 0 | J26: 1 | K26: 0
A27: Дёс | B27: =SUM(C27:K27) -> 2 | C27: 1 | D27: 0 | E27: 0 | F27: 0 | G27: 0 | H27: 0 | I27: 0 | J27: 1 | K27: 0
A28: Костян | B28: =SUM(C28:K28) -> 1 | D28: 0 | E28: 0 | F28: 0 | G28: 0 | H28: 0 | I28: 0 | J28: 1 | K28: 0
A29: Вадик | B29: =SUM(C29:K29) -> 1 | D29: 0 | E29: 0 | F29: 0 | G29: 0 | H29: 1 | I29: 0 | J29: 0 | K29: 0
A30: Чен | B30: =SUM(C30:K30) -> 1 | D30: 0 | E30: 0 | F30: 0 | G30: 1 | H30: 0 | I30: 0 | J30: 0 | K30: 0
A31: Пашок | B31: =SUM(C31:K31) -> 1 | D31: 1 | E31: 0 | F31: 0 | G31: 0 | H31: 0 | I31: 0 | J31: 0 | K31: 0
A32: Саня С | B32: =SUM(C32:K32) -> 0 | D32: 0 | E32: 0 | F32: 0 | G32: 0 | H32: 0 | I32: 0 | J32: 0 | K32: 0
A33: Самат | B33: =SUM(C33:K33) -> 0 | D33: 0 | E33: 0 | F33: 0 | G33: 0 | H33: 0 | I33: 0 | J33: 0 | K33: 0
A34: Дор | B34: =SUM(C34:K34) -> 0 | D34: 0 | E34: 0 | F34: 0 | G34: 0 | H34: 0 | I34: 0 | J34: 0 | K34: 0
A35: Серёга | B35: =SUM(C35:K35) -> 0 | D35: 0 | E35: 0 | F35: 0 | G35: 0 | H35: 0 | I35: 0 | J35: 0 | K35: 0

Sheet все бани
A1: Страна | B1: Регион | C1: =SUM(D8:AJ1620) -> 267 | D1: Ден | E1: Диман | F1: Шурик | G1: Хвост | H1: Денис | I1: Леха | J1: Фил | K1: Витёк | L1: Арс | M1: Женёк В | N1: Даня | O1: Ахмед | P1: Данюс | Q1: Махмуд | R1: Король | S1: Alex B | T1: Чен | U1: Миша П | V1: Женёк З | W1: Симба | X1: Жанат | Y1: Леха С | Z1: Макс | AA1: Пашок | AB1: Дёс | AC1: Костян | AD1: Толмач | AE1: Саня С | AF1: Вадик | AG1: Самат | AH1: Дор | AI1: Серёга | AJ1: san4ony
C2: Компания | D2: 8 | E2: 12 | F2: 9 | G2: 5 | H2: 0 | I2: 13 | J2: 11 | K2: 16 | L2: 6 | M2: 9 | N2: 4 | O2: 0 | P2: 0 | Q2: 6 | R2: 0 | S2: 2 | T2: 0 | U2: 0 | V2: 1 | W2: 2 | X2: 4 | Y2: 0 | Z2: 5 | AA2: 1 | AB2: 2 | AC2: 1 | AD2: 1 | AE2: 0 | AF2: 3 | AG2: 0 | AH2: 0 | AI2: 0 | AJ2: 2
C3: Региональная | D3: 3 | E3: 4 | F3: 17 | G3: 3 | H3: 5 | I3: 11 | J3: 3 | K3: 7 | L3: 5 | M3: 11 | N3: 3 | O3: 4 | P3: 2 | Q3: 3 | R3: 2 | S3: 3 | T3: 2 | U3: 3 | V3: 4 | W3: 2 | X3: 2 | Y3: 3 | Z3: 3 | AA3: 2 | AB3: 2 | AC3: 2 | AD3: 4 | AE3: 0 | AF3: 2 | AG3: 0 | AH3: 0 | AI3: 0 | AJ3: 4
C4: Общественная | D4: 15 | E4: 11 | F4: 14 | G4: 5 | H4: 1 | I4: 14 | J4: 11 | K4: 13 | L4: 7 | M4: 12 | N4: 1 | O4: 5 | P4: 3 | Q4: 4 | R4: 1 | S4: 4 | T4: 1 | U4: 2 | V4: 1 | W4: 0 | X4: 1 | Y4: 0 | Z4: 1 | AA4: 0 | AB4: 2 | AC4: 0 | AD4: 1 | AE4: 0 | AF4: 1 | AG4: 0 | AH4: 0 | AI4: 0 | AJ4: 9
C5: Долгая (>2,5ч) | D5: 13 | E5: 10 | F5: 8 | G5: 6 | H5: 2 | I5: 13 | J5: 7 | K5: 13 | L5: 12 | M5: 7 | N5: 2 | O5: 5 | P5: 6 | Q5: 4 | R5: 1 | S5: 4 | T5: 0 | U5: 2 | V5: 1 | W5: 1 | X5: 2 | Y5: 1 | Z5: 2 | AA5: 0 | AB5: 2 | AC5: 1 | AD5: 1 | AE5: 0 | AF5: 1 | AG5: 0 | AH5: 0 | AI5: 0 | AJ5: 10
C6: Ультра Уникальные | D6: 0 | E6: 2 | F6: 18 | G6: 1 | H6: 3 | I6: 13 | J6: 3 | K6: 9 | L6: 1 | M6: 8 | N6: 1 | O6: 1 | P6: 1 | Q6: 1 | R6: 0 | S6: 1 | T6: 1 | U6: 2 | V6: 1 | W6: 1 | X6: 0 | Y6: 2 | Z6: 0 | AA6: 1 | AB6: 0 | AC6: 0 | AD6: 2 | AE6: 0 | AF6: 0 | AG6: 0 | AH6: 0 | AI6: 0 | AJ6: 5
C7: Уникальные | D7: =COUNT(D8:D4620) -> 10 | E7: =COUNT(E8:E4620) -> 12 | F7: =COUNT(F8:F4620) -> 20 | G7: =COUNT(G8:G4620) -> 7 | H7: =COUNT(H8:H4620) -> 7 | I7: =COUNT(I8:I4620) -> 17 | J7: =COUNT(J8:J4620) -> 11 | K7: =COUNT(K8:K4620) -> 18 | ... AJ7: =COUNT(AJ8:AJ4620) -> 6
A8: Австрия | B8: Вена | C8: Паппенхайм2
A9: Австрия | B9: Вена | C9: Apostelbad | F9: 1
A10: Австрия | B10: Вена | C10: Dublinger
A11: Австрия | B11: Вена | C11: Jorgerbad
A12: Австрия | C12: 1р аква дом
A13: Австрия | C13: 2р аква дом
A14: Австрия | C14: Таурен Спа
A15: Австрия | C15: Römertherme Baden
A16: Австрия | C16: weberstube
A17: Армения | B17: Ереван | C17: Ереван, Cross resort
A18: Армения | B18: Ереван | C18: Ереван, Ibiza spa
A19: Армения | B19: Ереван | C19: Ереван, Ofuro spa
A20: Армения | B20: Ереван | C20: Ереванская
A21: Беларусь | B21: Минск | C21: Минск, баня 1
A22: Беларусь | B22: Минск | C22: Минск, баня 11
A23: Беларусь | B23: Минск | C23: Минск, баня 13
A24: Беларусь | B24: Минск | C24: Минск, баня 7
A25: Беларусь | B25: Минск | C25: Минск, баня 8
A26: Беларусь | B26: Минск | C26: Минск, Лазня
A27: Беларусь | B27: Минск | C27: Минск, Президент
A28: Беларусь | B28: Минск | C28: Минск, Фристайл
A29: Беларусь | B29: Минск | C29: Минск, the Баня
A30: Бельгия | B30: Фландрия западная | C30: Гест хаус скиндлес | F30: 1 | I30: 1 | V30: 1 | AA30: 1 | AD30: 1
A31: Боливия | C31: Боливия, Palacio de Sal
A32: Венгрия | B32: Будапешт | C32: Будапешт, Сечени
A33: Гватемала | B33: Гватемала | C33: Гватемала, Westin camino hotel
A34: Германия | B34: Берлин | C34: Берлин, Babor
A35: Германия | B35: Берлин | C35: Берлин, Liquidrom
A36: Германия | B36: Берлин | C36: Берлин, Park Inn
A37: Германия | B37: Mecklenburg-Vorpommern | C37: Дом отдыха "Три чайки", Zierow | F37: 1
A38: Германия | B38: Mecklenburg-Vorpommern | C38: De Poeler Drift 5А, | F38: 1
A39: Германия | B39: Schleswig-Holstein | C39: Campusbad Фленсбург | F39: 1
A40: Германия | C40: Германия, Tropical island
...

Sheet Регламент
A1: ПОЛОЖЕНИЕ О ЧЕТВЕРТОМ ЧЕМПИОНАТЕ ЕБЛ 1. Чемпионат ЕБЛ — ежегодное соревнование, проводящееся Евразийской банной лигой (ЕБЛ) с целью популяризации общественных бань. 2. В чемпионате принимают участие все участники группы ОУД. В чемпионате не могут принимать участие другие участники. Если участник вступает в группу ОУД в середине года, очки в зачет чемпионата ЕБЛ начинают ему начисляться с дня, следующего за днем вступления в группу. Если участник покидает группу ОУД, очки в зачет чемпионата ЕБЛ перестают ему начисляться с этого момента. 3. Под баней понимается специализированное для термических процедур, нагретое выше 50 °C помещение, в котором участник пребывает в раздетом виде. К баням относятся как общественные (городские) бани, так и индивидуальные банные помещения, включая ночные сауны, фитнесы и аквапарки с саунами, домашние сауны и переносные (разборные) бани. 4. В отдельную подкатегорию выделяются общественные бани, которые в целях настоящего регламента определяются как бани с выделенными мужскими часами/мужским днем в своем расписании или отдельными мужскими разрядами. В случае неопределенности решение об отнесении бани к общественной принимает комиссия. 5. Очки в чемпионате ЕБЛ начисляются за поход в баню. Очки за данный поход начисляются игроку при выполнении следующих условий: 1) поход в баню длился не менее 1 часа, 2) это был первый поход в данную баню за данные сутки, 3) поход документирован постом любого из участников чемпионата в телеграм-группу в тот же день. 6. Подсчет очков проводится еженедельно. Баня попадает в неделю, если участник зашел в нее не позднее 22:59 МСК воскресенья и прислал в этот же день информацию в группу. В случае, если информация о походе в баню прислана позже указанного срока, она попадает в следующую неделю. 7. По каждому игроку каждую неделю подсчитывается количество посещенных бань. Участники ранжируются по убыванию в зависимости от общего количества посещенных бань за неделю. Участнику, занявшему первое место, начисляется 15 очков, второе место — 12 очков, третье место — 10 очков, четвертое место — 8 очков, пятое место — 6 очков, шестое место — 4 очка, седьмое место – 2 очка, 8 место – 1 очко. Участникам, занявшим девятое и последующее места, начисляется 0 очков. В случае, если участники поделили места, им начисляется среднее арифметическое от количества баллов за эти места с округлением до десятых. Например, если 4 участника заняли 7—10 места, им начисляются по (2 + 1 + 0 + 0)/4 = 0,8 очков. Участники, не посетившие ни одной бани, получают 0 очков. 8. В случае, если ни один из участников за неделю не посетил ни одной из бань, неделя исключается из розыгрыша. 9. Очки также начисляются за факт посещения бани. За каждое посещение бани участнику начисляется 1 очко. Очки получают в т. ч. те участники, которые получили 0 очков в розыгрыше общего количества бань. 10. За каждое посещение общественной бани начисляется одно дополнительное очко. 11. В случае, если баня посещена группой, в которую входит от 3 до 5 участников ЕБЛ, каждому участнику за такое посещение дополнительно начисляется по 1 очку (категория К). Если в группе от 6 до 8 человек, каждому её участнику начисляется по 2 очка (категория КК), 9 человек и выше — по 3 очка (категория ККК). Посещение считается групповым, если участники были в бане в пределах календарных суток по московскому времени. 12. Дополнительно подсчитывается количество посещенных каждым участником уникальных бань. Уникальными считаются бани, размещенные в разных зданиях, а также бани, размещенные в одном здании, но считающиеся разными разрядами (каждый разряд снабжен отдельным входом по отдельному билету). Банные помещения одного аквапарка/фитнеса/отеля, разные срубы одной необщественной бани считаются одной баней (одним разрядом). За каждую уникальную (в пределах 2026 года) посещенную баню участник получает еще 1 очко (т. е. суммарно за посещение такой бани в первый раз участник получает 2 очка). 13. Также очки начисляются за посещение ультрауникальных бань — тех, в которых ни один из участников ЕБЛ ранее не был в 2023—2026 гг. За ультрауникальную баню каждый из участников, посетивших ее группой впервые (в пределах одного дня) в ЕБЛ, получает еще одно очко. За такое посещение бани участник суммарно получит 3 очка (не считая коллективных, региональных, общественных начислений). 14. Кроме того, очки начисляются за посещение бань в каждом регионе каждой страны. Под регионом понимается административно-территориальная единица первого уровня. Для РФ это субъект федерации, для Белоруссии, Казахстана, Армении – область, для Австрии и Германии – земля, для Грузии и Латвии – край, для Испании и Италии – историческая область, для Кипра – район, для Нидерландов, Таиланда, Турции – провинция, для ОАЭ – эмират, для США – штат, для Франции – регион, для Швейцарии – кантон, для Эстонии – уезд, для Японии – префектура. За каждый новый для себя регион в 2026 году участник получает +1 очко, за каждую новую страну – еще +1 очко. 15. Участник получает +1 очко в случае, если документально подтверждает свое пребывание в бане длительностью более 150 минут. Документальными свидетельствами являются фотографии участника, банного интерьера и экстерьера, снабженные выполненными вручную или автоматически (с помощью средств социальной сети) отметками о времени входа и выхода. Бани без двойной отметки воспринимаются как посещенные на 1 час, за них начисляется только 1 очко. При групповом посещении бани каждый участник должен самостоятельно озаботиться документированием своего посещения. 16. Очки каждого участника за все недели в течение года складываются. 17. Победителем чемпионата объявляется участник, набравший максимальное количество очков в течение года. В случае равенства этого показателя победитель выявляется по дополнительному показателю — количеству посещенных в течение года бань. 18. Чемпионат длится с 1 января 2026 года по 31 декабря 2026 года. Недели 1-4 января и 28-31 декабря дает баллы за места наравне с остальными неделями. 19. Все спорные ситуации разбираются Комиссией ЕБЛ. Секретарем Комиссии является Виктор Кудрявцев. 20. Турнирную таблицу ведет секретарь Комиссии ЕБЛ. 21. Чемпионат ЕБЛ является отборочным для Кубка ЕБЛ. Участники, занявшие 16 первых мест на дату начала Кубка (будет определена в регламенте Кубка), проходят в Кубок. Wild-card на Кубок получают чемпионы ЕБЛ прошлых лет: Филипп Лысенко, Дмитрий Радомский и Денис Мамонтов. Wild-card на Кубок получают победители Кубков прошлых лет: Ахмед Саидалиев, Дмитрий Радомский и команда Евгения Иванова и Дениса Киреева. Отдельный wild-card на одно место имеет также Комиссия. Если участник проходит в Кубок и без использования wild-card, то его wild-card в данном кубке не используется.

Sheet 2025 Общий зачет
A1: =SUM(C2:G34)-'2025 все бани'!B1-SUM('2025 все бани'!C2:AJ5) -> 0 | B1: Итого | C1: кол-во | D1: Уник | E1: УУник | F1: Дол | G1: комп | H1: W53 | I1: W52 | J1: W51 | K1: W50 | L1: W49 | M1: W48 | N1: W47 | O1: W46 | P1: W45 | Q1: W44 | R1: W43 | S1: W42 | T1: W41 | U1: W40 | V1: W39 | W1: W38 | X1: W37 | Y1: W36 | Z1: W35 | AA1: W34 | AB1: W33 | AC1: W32 | AD1: W31 | AE1: W30 | AF1: W29 | AG1: W28 | AH1: W27 | AI1: W26 | AJ1: W25 | AK1: W24 | AL1: W23 | AM1: W22 | AN1: W21 | AO1: W20 | AP1: W19 | AQ1: W18 | AR1: W17 | AS1: W16 | AT1: W15 | AU1: W14 | AV1: W13 | AW1: W12 | AX1: W11 | AY1: W10 | AZ1: W9 | BA1: W8 | BB1: W7 | BC1: W6 | BD1: W5 | BE1: W4 | BF1: W3 | BG1: W2 | BH1: W1
A2: Ден | B2: =SUM(C2:BH2) -> 662.575 | C2: =VLOOKUP(A2,'2025 недельный зачет'!$A:$B,2,FALSE) -> 162 | D2: =HLOOKUP(A2,'2025 все бани'!$1:$5,5,FALSE) -> 54 | E2: =HLOOKUP(A2,'2025 все бани'!$1:$5,4,FALSE) -> 16 | F2: =HLOOKUP(A2,'2025 все бани'!$1:$5,3,FALSE) -> 79 | G2: =HLOOKUP(A2,'2025 все бани'!$1:$5,2,FALSE) -> 48 | H2: 0.125 | I2: =1/6 -> 0.16666667 | J2: 3 | K2: 5 | L2: 0 | M2: 7 | N2: 10 | O2: 10 | P2: 8.5 | Q2: 1.6666667 | R2: 8.5 | S2: 10 | T2: 5 | U2: =11/6 -> 1.8333333 | V2: 10 | W2: 5 | X2: =22/3 -> 7.3333333 | Y2: 10 | Z2: 8.5 | AA2: 0 | AB2: 4 | AC2: 10 | AD2: 0.5 | AE2: 0 | AF2: 0 | AG2: 2 | AH2: 7 | AI2: =18/6 -> 3 | AJ2: 8.5 | AK2: 10 | AL2: 8.5 | AM2: 5 | AN2: =11/4 -> 2.75 | AO2: =22/3 -> 7.3333333 | AP2: 0 | AQ2: 4 | AR2: 8.5 | AS2: 10 | AT2: =25/4 -> 6.25 | AU2: 8.5 | AV2: 10 | AW2: 6 | AX2: =22/3 -> 7.3333333 | AY2: =11/5 -> 2.2 | AZ2: 10 | BA2: =22/3 -> 7.3333333 | BB2: 10 | BC2: 10 | BD2: =25/4 -> 6.25 | BE2: 6 | BF2: 10 | BG2: 1 | BH2: 0
A3: Шурик | B3: =SUM(C3:BH3) -> 513.2 | C3: =VLOOKUP(A3,'2025 недельный зачет'!$A:$B,2,FALSE) -> 107 | D3: =HLOOKUP(A3,'2025 все бани'!$1:$5,5,FALSE) -> 95 | E3: =HLOOKUP(A3,'2025 все бани'!$1:$5,4,FALSE) -> 65 | F3: =HLOOKUP(A3,'2025 все бани'!$1:$5,3,FALSE) -> 48 | G3: =HLOOKUP(A3,'2025 все бани'!$1:$5,2,FALSE) -> 33 | H3: 10 | I3: 0 | J3: 0 | K3: 8.5 | L3: 0 | M3: 10 | N3: 0 | O3: =6/8 -> 0.75 | P3: 0 | Q3: 0 | R3: 0 | S3: 0 | T3: 10 | U3: =11/6 -> 1.8333333 | V3: 7 | W3: 0.5 | X3: =22/3 -> 7.3333333 | Y3: 0 | Z3: 5 | AA3: =22/3 -> 7.3333333 | AB3: 0 | AC3: 0 | AD3: 0.5 | AE3: 8.5 | AF3: 2.2 | AG3: 10 | AH3: 10 | AI3: 10 | AJ3: 0 | AK3: 0 | AL3: 0 | AM3: 0 | AN3: 10 | AO3: 0 | AP3: 10 | AQ3: 2 | AR3: =11/5 -> 2.2 | AS3: 0 | AT3: 0 | AU3: 0 | AV3: 0.3 | AW3: =1/4 -> 0.25 | AX3: 0 | AY3: 0 | AZ3: 0 | BA3: 0 | BB3: 0.75 | BC3: =17/4 -> 4.25 | BD3: =25/4 -> 6.25 | BE3: 2.5 | BF3: 5 | BG3: 6 | BH3: =25/4 -> 6.25
A4: Диман | B4: =SUM(C4:BH4) -> 488.00758 | C4: =VLOOKUP(A4,'2025 недельный зачет'!$A:$B,2,FALSE) -> 108 | D4: =HLOOKUP(A4,'2025 все бани'!$1:$5,5,FALSE) -> 71 | E4: =HLOOKUP(A4,'2025 все бани'!$1:$5,4,FALSE) -> 21 | F4: =HLOOKUP(A4,'2025 все бани'!$1:$5,3,FALSE) -> 90 | G4: =HLOOKUP(A4,'2025 все бани'!$1:$5,2,FALSE) -> 62 | H4: 0 | I4: =1/6 -> 0.16666667 | J4: 6 | K4: 0 | L4: 2 | M4: 0.16666667 | N4: =6/10 -> 0.6 | O4: 0 | P4: 8.5 | Q4: 3 | R4: 0 | S4: =18/5 -> 3.6 | T4: 5 | U4: 8.5 | V4: 0 | W4: 0.5 | X4: 0 | Y4: 1 | Z4: 0 | AA4: 0 | AB4: 0 | AC4: 0 | AD4: =25/4 -> 6.25 | AE4: 0 | AF4: 2.2 | AG4: 0 | AH4: 4 | AI4: =18/6 -> 3 | AJ4: =11/4 -> 2.75 | AK4: =1/11 -> 0.090909091 | AL4: 0 | AM4: 10 | AN4: =11/4 -> 2.75 | AO4: =6/5 -> 1.2 | AP4: 2 | AQ4: =1/6 -> 0.16666667 | AR4: =11/5 -> 2.2 | AS4: 0.5 | AT4: =25/4 -> 6.25 | AU4: 8.5 | AV4: 7 | AW4: 2.5 | AX4: =22/3 -> 7.3333333 | AY4: =11/5 -> 2.2 | AZ4: 7 | BA4: =22/3 -> 7.3333333 | BB4: 5 | BC4: =17/4 -> 4.25 | BD4: 0 | BE4: 2.5 | BF4: 0 | BG4: 0 | BH4: 0
A5: Хвост | B5: =SUM(C5:BH5) -> 414.78301 | C5: =VLOOKUP(A5,'2025 недельный зачет'!$A:$B,2,FALSE) -> 104 | D5: =HLOOKUP(A5,'2025 все бани'!$1:$5,5,FALSE) -> 74 | E5: =HLOOKUP(A5,'2025 все бани'!$1:$5,4,FALSE) -> 34 | F5: =HLOOKUP(A5,'2025 все бани'!$1:$5,3,FALSE) -> 71 | G5: =HLOOKUP(A5,'2025 все бани'!$1:$5,2,FALSE) -> 37 | H5: 0.125 | I5: 3 | J5: 10 | K5: =3/5 -> 0.6 | L5: 5 | M5: 2.5 | N5: 0 | O5: 0 | P5: =1/7 -> 0.14285714 | Q5: 1.6666667 | R5: 0 | S5: 0 | T5: 1.5 | U5: 8.5 | V5: 1.2222222 | W5: 10 | X5: =1/9 -> 0.11111111 | Y5: 1 | Z5: 1 | AA5: 2 | AB5: 0 | AC5: 0 | AD5: 0.5 | AE5: 0 | AF5: 2.2 | AG5: 0 | AH5: 0 | AI5: 0 | AJ5: =11/4 -> 2.75 | AK5: =1/11 -> 0.090909091 | AL5: 8.5 | AM5: =1/3 -> 0.33333333 | AN5: 0 | AO5: =6/5 -> 1.2 | AP5: 0 | AQ5: 0 | AR5: 0 | AS5: 0.5 | AT5: 2 | AU5: 2 | AV5: 4 | AW5: 2.5 | AX5: 1.5 | AY5: 0 | AZ5: 0.090909091 | BA5: 0 | BB5: 5 | BC5: 0 | BD5: 0 | BE5: 6 | BF5: 0 | BG5: 1 | BH5: =25/4 -> 6.25
A6: Леха | B6: =SUM(C6:BH6) -> 391.70599 | C6: =VLOOKUP(A6,'2025 недельный зачет'!$A:$B,2,FALSE) -> 99 | D6: =HLOOKUP(A6,'2025 все бани'!$1:$5,5,FALSE) -> 55 | E6: =HLOOKUP(A6,'2025 все бани'!$1:$5,4,FALSE) -> 33 | F6: =HLOOKUP(A6,'2025 все бани'!$1:$5,3,FALSE) -> 37 | G6: =HLOOKUP(A6,'2025 все бани'!$1:$5,2,FALSE) -> 39 | H6: 6 | I6: =1/6 -> 0.16666667 | J6: 1.5 | K6: 8.5 | L6: 0 | M6: 0 | N6: =6/10 -> 0.6 | O6: =6/8 -> 0.75 | P6: =1/7 -> 0.14285714 | Q6: 10 | R6: 0 | S6: =18/5 -> 3.6 | T6: 5 | U6: =11/6 -> 1.8333333 | V6: 1.2222222 | W6: 0.5 | X6: 0 | Y6: 1 | Z6: 0 | AA6: =22/3 -> 7.3333333 | AB6: 0 | AC6: 0 | AD6: 0 | AE6: 0 | AF6: 0 | AG6: 0 | AH6: 0.5 | AI6: =18/6 -> 3 | AJ6: 0 | AK6: 7 | AL6: 0.75 | AM6: 5 | AN6: 0 | AO6: =22/3 -> 7.3333333 | AP6: 6 | AQ6: 10 | AR6: 0 | AS6: 7 | AT6: =25/4 -> 6.25 | AU6: 5 | AV6: 0.3 | AW6: 0 | AX6: 1.5 | AY6: 0 | AZ6: 3.3333333 | BA6: 0 | BB6: 0.75 | BC6: =17/4 -> 4.25 | BD6: =25/4 -> 6.25 | BE6: =1/11 -> 0.090909091 | BF6: 0 | BG6: 0 | BH6: =25/4 -> 6.25
A7: Фил | B7: =SUM(C7:BH7) -> 369.52778 | C7: =VLOOKUP(A7,'2025 недельный зачет'!$A:$B,2,FALSE) -> 86 | D7: =HLOOKUP(A7,'2025 все бани'!$1:$5,5,FALSE) -> 66 | E7: =HLOOKUP(A7,'2025 все бани'!$1:$5,4,FALSE) -> 37 | F7: =HLOOKUP(A7,'2025 все бани'!$1:$5,3,FALSE) -> 55 | G7: =HLOOKUP(A7,'2025 все бани'!$1:$5,2,FALSE) -> 56 | H7: 0.125 | I7: =1/6 -> 0.16666667 | J7: 1.5 | K7: =3/5 -> 0.6 | L7: 10 | M7: 5 | N7: =6/10 -> 0.6 | O7: =6/8 -> 0.75 | P7: 0 | Q7: 6 | R7: =11/4 -> 2.75 | S7: 0 | T7: 0 | U7: =11/6 -> 1.8333333 | V7: 0 | W7: 5 | X7: =1/9 -> 0.11111111 | Y7: 0 | Z7: 1 | AA7: 0 | AB7: 0 | AC7: 0 | AD7: 0.5 | AE7: =11/4 -> 2.75 | AF7: 8.5 | AG7: 2 | AH7: 4 | AI7: =18/6 -> 3 | AJ7: 0 | AK7: 0 | AL7: 0.75 | AM7: 0 | AN7: 0 | AO7: 0 | AP7: 0 | AQ7: 0 | AR7: 8.5 | AS7: 0 | AT7: =1/6 -> 0.16666667 | AU7: 0 | AV7: 0.3 | AW7: =1/4 -> 0.25 | AX7: 0 | AY7: 0 | AZ7: 0 | BA7: 0 | BB7: 0 | BC7: 0 | BD7: 0 | BE7: 0 | BF7: 0 | BG7: 3 | BH7: =3/8 -> 0.375
A8: Витёк | B8: =SUM(C8:BH8) -> 347.29571 | C8: =VLOOKUP(A8,'2025 недельный зачет'!$A:$B,2,FALSE) -> 79 | D8: =HLOOKUP(A8,'2025 все бани'!$1:$5,5,FALSE) -> 61 | E8: =HLOOKUP(A8,'2025 все бани'!$1:$5,4,FALSE) -> 29 | F8: =HLOOKUP(A8,'2025 все бани'!$1:$5,3,FALSE) -> 53 | G8: =HLOOKUP(A8,'2025 все бани'!$1:$5,2,FALSE) -> 58 | H8: 6 | I8: 0 | J8: 0 | K8: 0 | L8: 0 | M8: 0.16666667 | N8: =6/10 -> 0.6 | O8: =6/8 -> 0.75 | P8: =10/3 -> 3.3333333 | Q8: 1.6666667 | R8: 0 | S8: 0 | T8: 0 | U8: 0 | V8: 1.2222222 | W8: 0 | X8: 0 | Y8: 0 | Z8: 1 | AA8: 2 | AB8: 4 | AC8: 0 | AD8: 0 | AE8: =11/4 -> 2.75 | AF8: 8.5 | AG8: 0 | AH8: 0 | AI8: 0 | AJ8: =11/4 -> 2.75 | AK8: =10/3 -> 3.3333333 | AL8: 0.75 | AM8: =1/3 -> 0.33333333 | AN8: 0 | AO8: 0 | AP8: 6 | AQ8: 4 | AR8: =11/5 -> 2.2 | AS8: 0.5 | AT8: =25/4 -> 6.25 | AU8: 0 | AV8: 0.3 | AW8: =1/4 -> 0.25 | AX8: 0 | AY8: 0 | AZ8: 0.090909091 | BA8: =22/3 -> 7.3333333 | BB8: 0.75 | BC8: 0 | BD8: 0 | BE8: =1/11 -> 0.090909091 | BF8: 0 | BG8: 0 | BH8: =3/8 -> 0.375
A9: Денис | B9: =SUM(C9:BH9) -> 297.67071 | C9: =VLOOKUP(A9,'2025 недельный зачет'!$A:$B,2,FALSE) -> 102 | D9: =HLOOKUP(A9,'2025 все бани'!$1:$5,5,FALSE) -> 36 | E9: =HLOOKUP(A9,'2025 все бани'!$1:$5,4,FALSE) -> 23 | F9: =HLOOKUP(A9,'2025 все бани'!$1:$5,3,FALSE) -> 24 | G9: =HLOOKUP(A9,'2025 все бани'!$1:$5,2,FALSE) -> 13 | H9: 0.125 | I9: 6 | J9: 6 | K9: =3/5 -> 0.6 | L9: 7 | M9: 0.16666667 | N9: 0 | O9: 0 | P9: 0 | Q9: 6 | R9: =11/4 -> 2.75 | S9: 0 | T9: 0 | U9: 0 | V9: 1.2222222 | W9: 0 | X9: 2.5 | Y9: 1 | Z9: 3 | AA9: 0 | AB9: 0 | AC9: 0 | AD9: 0 | AE9: 0 | AF9: 0 | AG9: 0 | AH9: 0 | AI9: =18/6 -> 3 | AJ9: 0 | AK9: =1/11 -> 0.090909091 | AL9: 0.75 | AM9: 0 | AN9: 0 | AO9: 0 | AP9: 0 | AQ9: 7 | AR9: 0 | AS9: 0 | AT9: 0 | AU9: 0 | AV9: 0 | AW9: 0 | AX9: 1.5 | AY9: 8.5 | AZ9: 0.090909091 | BA9: 1.5 | BB9: 5 | BC9: =17/4 -> 4.25 | BD9: =25/4 -> 6.25 | BE9: 10 | BF9: 5 | BG9: 10 | BH9: =3/8 -> 0.375
A10: Арс | B10: =SUM(C10:BH10) -> 267.54058 | C10: =VLOOKUP(A10,'2025 недельный зачет'!$A:$B,2,FALSE) -> 71 | D10: =HLOOKUP(A10,'2025 все бани'!$1:$5,5,FALSE) -> 34 | E10: =HLOOKUP(A10,'2025 все бани'!$1:$5,4,FALSE) -> 6 | F10: =HLOOKUP(A10,'2025 все бани'!$1:$5,3,FALSE) -> 59 | G10: =HLOOKUP(A10,'2025 все бани'!$1:$5,2,FALSE) -> 39 | H10: 0.125 | I10: =1/6 -> 0.16666667 | J10: 0 | K10: 0 | L10: 0 | M10: 2.5 | N10: =6/10 -> 0.6 | O10: 6 | P10: =1/7 -> 0.14285714 | Q10: 1.6666667 | R10: 8.5 | S10: 0 | T10: 0 | U10: =11/6 -> 1.8333333 | V10: 1.2222222 | W10: 5 | X10: =1/9 -> 0.11111111 | Y10: 0 | Z10: 0 | AA10: 0 | AB10: 1.5 | AC10: 0 | AD10: 0.5 | AE10: 0 | AF10: 2.2 | AG10: 0 | AH10: 0.5 | AI10: 0 | AJ10: 8.5 | AK10: =1/11 -> 0.090909091 | AL10: 0 | AM10: =1/3 -> 0.33333333 | AN10: 0 | AO10: 0 | AP10: 2 | AQ10: 0 | AR10: =11/5 -> 2.2 | AS10: 0.5 | AT10: =1/6 -> 0.16666667 | AU10: 2 | AV10: 4 | AW10: 6 | AX10: 0 | AY10: 0 | AZ10: 0.090909091 | BA10: 0 | BB10: 0 | BC10: 0 | BD10: 0 | BE10: =1/11 -> 0.090909091 | BF10: 0 | BG10: 0 | BH10: 0
A11: Женёк В | B11: =SUM(C11:BH11) -> 266.9548 | C11: =VLOOKUP(A11,'2025 недельный зачет'!$A:$B,2,FALSE) -> 71 | D11: =HLOOKUP(A11,'2025 все бани'!$1:$5,5,FALSE) -> 47 | E11: =HLOOKUP(A11,'2025 все бани'!$1:$5,4,FALSE) -> 23 | F11: =HLOOKUP(A11,'2025 все бани'!$1:$5,3,FALSE) -> 23 | G11: =HLOOKUP(A11,'2025 все бани'!$1:$5,2,FALSE) -> 20 | H11: 0.125 | I11: 6 | J11: 0 | K11: 0 | L11: 0 | M11: 0.16666667 | N11: =6/10 -> 0.6 | O11: 0 | P11: =10/3 -> 3.3333333 | Q11: 0 | R11: 0 | S11: 0 | T11: 0 | U11: 0 | V11: 1.2222222 | W11: 0 | X11: 0 | Y11: 1 | Z11: 8.5 | AA11: =22/3 -> 7.3333333 | AB11: 8.5 | AC11: 7 | AD11: =25/4 -> 6.25 | AE11: =11/4 -> 2.75 | AF11: 0 | AG11: 0 | AH11: 0 | AI11: 0 | AJ11: 0 | AK11: 0 | AL11: 0 | AM11: 0 | AN11: 0 | AO11: =22/3 -> 7.3333333 | AP11: 0 | AQ11: 0 | AR11: 0 | AS11: 0.5 | AT11: 0 | AU11: 0 | AV11: 0 | AW11: 0 | AX11: 0 | AY11: 8.5 | AZ11: 0 | BA11: 0 | BB11: 0 | BC11: 0 | BD11: 1.5 | BE11: =1/11 -> 0.090909091 | BF11: 0 | BG11: 6 | BH11: =25/4 -> 6.25
A12: Ахмед | B12: =SUM(C12:BH12) -> 231.65328 | C12: =VLOOKUP(A12,'2025 недельный зачет'!$A:$B,2,FALSE) -> 64 | D12: =HLOOKUP(A12,'2025 все бани'!$1:$5,5,FALSE) -> 24 | E12: =HLOOKUP(A12,'2025 все бани'!$1:$5,4,FALSE) -> 11 | F12: =HLOOKUP(A12,'2025 все бани'!$1:$5,3,FALSE) -> 55 | G12: =HLOOKUP(A12,'2025 все бани'!$1:$5,2,FALSE) -> 23 | H12: 0 | I12: =1/6 -> 0.16666667 | J12: 0 | K12: 0 | L12: 0 | M12: 0.16666667 | N12: 6 | O12: =6/8 -> 0.75 | P12: 0 | Q12: 0 | R12: =11/4 -> 2.75 | S12: 0 | T12: 0 | U12: 0 | V12: 1.2222222 | W12: 0.5 | X12: =22/3 -> 7.3333333 | Y12: 1 | Z12: 0 | AA12: 2 | AB12: 0 | AC12: =11/4 -> 2.75 | AD12: =25/4 -> 6.25 | AE12: 0 | AF12: 2.2 | AG12: 6 | AH12: 0.5 | AI12: 0 | AJ12: 0 | AK12: =1/11 -> 0.090909091 | AL12: 0.75 | AM12: 0 | AN12: 0 | AO12: =6/5 -> 1.2 | AP12: 0 | AQ12: 0 | AR12: 0 | AS12: 4 | AT12: =1/6 -> 0.16666667 | AU12: 0 | AV12: 0.3 | AW12: 0 | AX12: 0 | AY12: 0 | AZ12: 0.090909091 | BA12: 1.5 | BB12: 0 | BC12: 0 | BD12: 1.5 | BE12: =1/11 -> 0.090909091 | BF12: 5 | BG12: 0 | BH12: =3/8 -> 0.375
A13: Данюс | B13: =SUM(C13:BH13) -> 213.52543 | C13: =VLOOKUP(A13,'2025 недельный зачет'!$A:$B,2,FALSE) -> 63 | D13: =HLOOKUP(A13,'2025 все бани'!$1:$5,5,FALSE) -> 31 | E13: =HLOOKUP(A13,'2025 все бани'!$1:$5,4,FALSE) -> 20 | F13: =HLOOKUP(A13,'2025 все бани'!$1:$5,3,FALSE) -> 41 | G13: =HLOOKUP(A13,'2025 все бани'!$1:$5,2,FALSE) -> 4 | H13: 0 | I13: 10 | J13: 0 | K13: 0 | L13: 2 | M13: 0 | N13: 0 | O13: =6/8 -> 0.75 | P13: =1/7 -> 0.14285714 | Q13: 1.6666667 | R13: 0 | S13: =18/5 -> 3.6 | T13: 1.5 | U13: 0 | V13: 0 | W13: 0 | X13: 0 | Y13: 1 | Z13: 0 | AA13: 0 | AB13: 0 | AC13: =11/4 -> 2.75 | AD13: 0 | AE13: 0 | AF13: 0 | AG13: 0 | AH13: 0 | AI13: 0 | AJ13: 0 | AK13: =10/3 -> 3.3333333 | AL13: 0.75 | AM13: 5 | AN13: 0 | AO13: =6/5 -> 1.2 | AP13: 0 | AQ13: =1/6 -> 0.16666667 | AR13: 0 | AS13: 0 | AT13: =1/6 -> 0.16666667 | AU13: 0 | AV13: 0 | AW13: 10 | AX13: =22/3 -> 7.3333333 | AY13: =11/5 -> 2.2 | AZ13: 0.090909091 | BA13: 0 | BB13: 0 | BC13: 0.5 | BD13: 0 | BE13: 0 | BF13: 0 | BG13: 0 | BH13: =3/8 -> 0.375
A14: Махмуд | B14: =SUM(C14:BH14) -> 199.74892 | C14: =VLOOKUP(A14,'2025 недельный зачет'!$A:$B,2,FALSE) -> 54 | D14: =HLOOKUP(A14,'2025 все бани'!$1:$5,5,FALSE) -> 30 | E14: =HLOOKUP(A14,'2025 все бани'!$1:$5,4,FALSE) -> 8 | F14: =HLOOKUP(A14,'2025 все бани'!$1:$5,3,FALSE) -> 35 | G14: =HLOOKUP(A14,'2025 все бани'!$1:$5,2,FALSE) -> 38 | H14: 0.125 | I14: 0 | J14: 0 | K14: 0 | L14: 0 | M14: 0 | N14: 0 | O14: 0 | P14: =1/7 -> 0.14285714 | Q14: 0 | R14: 0 | S14: 0 | T14: 0 | U14: 0 | V14: 0 | W14: 0.5 | X14: 0 | Y14: 0 | Z14: 0 | AA14: 0 | AB14: 8.5 | AC14: =11/4 -> 2.75 | AD14: 0.5 | AE14: =11/4 -> 2.75 | AF14: 0 | AG14: 6 | AH14: 0.5 | AI14: 0 | AJ14: 0 | AK14: =1/11 -> 0.090909091 | AL14: 0 | AM14: 2 | AN14: 7 | AO14: 0 | AP14: 2 | AQ14: =1/6 -> 0.16666667 | AR14: 0 | AS14: 0 | AT14: =1/6 -> 0.16666667 | AU14: 0 | AV14: 0 | AW14: 0 | AX14: 0 | AY14: 0 | AZ14: 0.090909091 | BA14: 0 | BB14: 0 | BC14: 0 | BD14: 0 | BE14: =1/11 -> 0.090909091 | BF14: 0 | BG14: 1 | BH14: =3/8 -> 0.375
A15: Даня | B15: =SUM(C15:BH15) -> 162.67551 | C15: =VLOOKUP(A15,'2025 недельный зачет'!$A:$B,2,FALSE) -> 65 | D15: =HLOOKUP(A15,'2025 все бани'!$1:$5,5,FALSE) -> 15 | E15: =HLOOKUP(A15,'2025 все бани'!$1:$5,4,FALSE) -> 4 | F15: =HLOOKUP(A15,'2025 все бани'!$1:$5,3,FALSE) -> 14 | G15: =HLOOKUP(A15,'2025 все бани'!$1:$5,2,FALSE) -> 23 | H15: 0 | I15: 0 | J15: 0 | K15: 0 | L15: 0 | M15: 0 | N15: 6 | O15: =6/8 -> 0.75 | P15: =10/3 -> 3.3333333 | Q15: 0 | R15: =11/4 -> 2.75 | S15: =18/5 -> 3.6 | T15: 0 | U15: 0 | V15: 0 | W15: 0 | X15: =1/9 -> 0.11111111 | Y15: 1 | Z15: 0 | AA15: 0 | AB15: 0 | AC15: 0 | AD15: =25/4 -> 6.25 | AE15: 0 | AF15: 0 | AG15: 0 | AH15: 0.5 | AI15: 0 | AJ15: 0 | AK15: =1/11 -> 0.090909091 | AL15: 0 | AM15: 0 | AN15: =11/4 -> 2.75 | AO15: =6/5 -> 1.2 | AP15: 0 | AQ15: =1/6 -> 0.16666667 | AR15: =11/5 -> 2.2 | AS15: 0.5 | AT15: =1/6 -> 0.16666667 | AU15: 2 | AV15: 0.3 | AW15: 0 | AX15: 1.5 | AY15: =11/5 -> 2.2 | AZ15: 0.090909091 | BA15: 1.5 | BB15: 0.75 | BC15: 0 | BD15: 0 | BE15: =1/11 -> 0.090909091 | BF15: 1.5 | BG15: 0 | BH15: =3/8 -> 0.375
A16: Король | B16: =SUM(C16:BH16) -> 153.24924 | C16: =VLOOKUP(A16,'2025 недельный зачет'!$A:$B,2,FALSE) -> 48 | D16: =HLOOKUP(A16,'2025 все бани'!$1:$5,5,FALSE) -> 23 | E16: =HLOOKUP(A16,'2025 все бани'!$1:$5,4,FALSE) -> 10 | F16: =HLOOKUP(A16,'2025 все бани'!$1:$5,3,FALSE) -> 27 | G16: =HLOOKUP(A16,'2025 все бани'!$1:$5,2,FALSE) -> 15 | H16: 0 | I16: 2 | J16: 0 | K16: =3/5 -> 0.6 | L16: 0 | M16: 0 | N16: =6/10 -> 0.6 | O16: =6/8 -> 0.75 | P16: 0 | Q16: 0 | R16: 0 | S16: 0 | T16: 0 | U16: 0 | V16: 0 | W16: 0 | X16: 2.5 | Y16: 0 | Z16: 0 | AA16: 0 | AB16: 0 | AC16: =11/4 -> 2.75 | AD16: 0 | AE16: 0 | AF16: 0 | AG16: 0 | AH16: 0.5 | AI16: =18/6 -> 3 | AJ16: 0 | AK16: =10/3 -> 3.3333333 | AL16: 0.75 | AM16: 0 | AN16: =11/4 -> 2.75 | AO16: 0 | AP16: 0 | AQ16: 0 | AR16: 0 | AS16: 4 | AT16: 0 | AU16: 0 | AV16: 0.3 | AW16: =1/4 -> 0.25 | AX16: 0 | AY16: =11/5 -> 2.2 | AZ16: 0.090909091 | BA16: 1.5 | BB16: 0 | BC16: 0.5 | BD16: 0 | BE16: 0 | BF16: 1.5 | BG16: 0 | BH16: =3/8 -> 0.375
A17: Alex B | B17: =SUM(C17:BH17) -> 120.57543 | C17: =VLOOKUP(A17,'2025 недельный зачет'!$A:$B,2,FALSE) -> 35 | D17: =HLOOKUP(A17,'2025 все бани'!$1:$5,5,FALSE) -> 18 | E17: =HLOOKUP(A17,'2025 все бани'!$1:$5,4,FALSE) -> 9 | F17: =HLOOKUP(A17,'2025 все бани'!$1:$5,3,FALSE) -> 22 | G17: =HLOOKUP(A17,'2025 все бани'!$1:$5,2,FALSE) -> 12 | H17: 0.125 | I17: 0 | J17: 0 | K17: 3 | L17: 2 | M17: 0 | N17: 0 | O17: 6 | P17: =1/7 -> 0.14285714 | Q17: 0 | R17: 0 | S17: 0 | T17: 0 | U17: =11/6 -> 1.8333333 | V17: 0 | W17: 0 | X17: 0 | Y17: 7 | Z17: 0 | AA17: 0 | AB17: 0 | AC17: 0 | AD17: 0 | AE17: 0 | AF17: 0 | AG17: 0 | AH17: 0 | AI17: 0 | AJ17: 0 | AK17: 0 | AL17: 0.75 | AM17: 0 | AN17: 0 | AO17: 0 | AP17: 0 | AQ17: 0 | AR17: 0 | AS17: 0 | AT17: 0 | AU17: 0 | AV17: 0.3 | AW17: 0 | AX17: 0 | AY17: 0 | AZ17: 3.3333333 | BA17: 0 | BB17: 0 | BC17: 0 | BD17: 0 | BE17: =1/11 -> 0.090909091 | BF17: 0 | BG17: 0 | BH17: 0
A18: Чен | B18: =SUM(C18:BH18) -> 64.00404 | C18: =VLOOKUP(A18,'2025 недельный зачет'!$A:$B,2,FALSE) -> 19 | D18: =HLOOKUP(A18,'2025 все бани'!$1:$5,5,FALSE) -> 10 | E18: =HLOOKUP(A18,'2025 все бани'!$1:$5,4,FALSE) -> 4 | F18: =HLOOKUP(A18,'2025 все бани'!$1:$5,3,FALSE) -> 13 | G18: =HLOOKUP(A18,'2025 все бани'!$1:$5,2,FALSE) -> 9 | H18: 0 | I18: 0 | J18: 0 | K18: 0 | L18: 0 | M18: 0 | N18: =6/10 -> 0.6 | O18: 0 | P18: 0 | Q18: 0 | R18: 0 | S18: 0 | T18: 0 | U18: 0 | V18: 1.2222222 | W18: 0 | X18: 0 | Y18: 0 | Z18: 0 | AA18: 0 | AB18: 0 | AC18: 0 | AD18: 0 | AE18: 0 | AF18: 0 | AG18: 2 | AH18: 0 | AI18: 0 | AJ18: 0 | AK18: 0 | AL18: 5 | AM18: 0 | AN18: 0 | AO18: 0 | AP18: 0 | AQ18: 0 | AR18: 0 | AS18: 0 | AT18: 0 | AU18: 0 | AV18: 0 | AW18: 0 | AX18: 0 | AY18: 0 | AZ18: 0.090909091 | BA18: 0 | BB18: 0 | BC18: 0 | BD18: 0 | BE18: =1/11 -> 0.090909091 | BF18: 0 | BG18: 0 | BH18: 0
A19: Женёк З | B19: =SUM(C19:BH19) -> 62.090909 | C19: =VLOOKUP(A19,'2025 недельный зачет'!$A:$B,2,FALSE) -> 13 | D19: =HLOOKUP(A19,'2025 все бани'!$1:$5,5,FALSE) -> 12 | E19: =HLOOKUP(A19,'2025 все бани'!$1:$5,4,FALSE) -> 4 | F19: =HLOOKUP(A19,'2025 все бани'!$1:$5,3,FALSE) -> 10 | G19: =HLOOKUP(A19,'2025 все бани'!$1:$5,2,FALSE) -> 13 | H19: 0 | I19: 0 | J19: 0 | K19: 0 | L19: 0 | M19: 0 | N19: 0 | O19: 0 | P19: 0 | Q19: 0 | R19: 0 | S19: 0 | T19: 0 | U19: 0 | V19: 0 | W19: 0 | X19: 0 | Y19: 0 | Z19: 0 | AA19: 0 | AB19: 1.5 | AC19: 0 | AD19: 0 | AE19: 8.5 | AF19: 0 | AG19: 0 | AH19: 0 | AI19: 0 | AJ19: 0 | AK19: 0 | AL19: 0 | AM19: 0 | AN19: 0 | AO19: 0 | AP19: 0 | AQ19: 0 | AR19: 0 | AS19: 0 | AT19: 0 | AU19: 0 | AV19: 0 | AW19: 0 | AX19: 0 | AY19: 0 | AZ19: 0 | BA19: 0 | BB19: 0 | BC19: 0 | BD19: 0 | BE19: =1/11 -> 0.090909091 | BF19: 0 | BG19: 0 | BH19: 0
A20: Миша П | B20: =SUM(C20:BH20) -> 41 | C20: =VLOOKUP(A20,'2025 недельный зачет'!$A:$B,2,FALSE) -> 14 | D20: =HLOOKUP(A20,'2025 все бани'!$1:$5,5,FALSE) -> 9 | E20: =HLOOKUP(A20,'2025 все бани'!$1:$5,4,FALSE) -> 1 | F20: =HLOOKUP(A20,'2025 все бани'!$1:$5,3,FALSE) -> 9 | G20: =HLOOKUP(A20,'2025 все бани'!$1:$5,2,FALSE) -> 8 | H20: 0 | I20: 0 | J20: 0 | K20: 0 | L20: 0 | M20: 0 | N20: 0 | O20: 0 | P20: 0 | Q20: 0 | R20: 0 | S20: 0 | T20: 0 | U20: 0 | V20: 0 | W20: 0 | X20: 0 | Y20: 0 | Z20: 0 | AA20: 0 | AB20: 0 | AC20: 0 | AD20: 0 | AE20: 0 | AF20: 0 | AG20: 0 | AH20: 0 | AI20: 0 | AJ20: 0 | AK20: 0 | AL20: 0 | AM20: 0 | AN20: 0 | AO20: 0 | AP20: 0 | AQ20: 0 | AR20: 0 | AS20: 0 | AT20: 0 | AU20: 0 | AV20: 0 | AW20: 0 | AX20: 0 | AY20: 0 | AZ20: 0 | BA20: 0 | BB20: 0 | BC20: 0 | BD20: 0 | BE20: 0 | BF20: 0 | BG20: 0 | BH20: 0
A21: Леха С | B21: =SUM(C21:BH21) -> 40.059524 | C21: =VLOOKUP(A21,'2025 недельный зачет'!$A:$B,2,FALSE) -> 10 | D21: =HLOOKUP(A21,'2025 все бани'!$1:$5,5,FALSE) -> 10 | E21: =HLOOKUP(A21,'2025 все бани'!$1:$5,4,FALSE) -> 2 | F21: =HLOOKUP(A21,'2025 все бани'!$1:$5,3,FALSE) -> 8 | G21: =HLOOKUP(A21,'2025 все бани'!$1:$5,2,FALSE) -> 7 | H21: 0 | I21: 0 | J21: 0 | K21: 0 | L21: 0 | M21: 0.16666667 | N21: 0 | O21: 0 | P21: =1/7 -> 0.14285714 | Q21: 0 | R21: 0 | S21: 0 | T21: 0 | U21: 0 | V21: 0 | W21: 0 | X21: 0 | Y21: 0 | Z21: 0 | AA21: 0 | AB21: 0 | AC21: 0 | AD21: 0 | AE21: 0 | AF21: 0 | AG21: 0 | AH21: 0 | AI21: 0 | AJ21: =11/4 -> 2.75 | AK21: 0 | AL21: 0 | AM21: 0 | AN21: 0 | AO21: 0 | AP21: 0 | AQ21: 0 | AR21: 0 | AS21: 0 | AT21: 0 | AU21: 0 | AV21: 0 | AW21: 0 | AX21: 0 | AY21: 0 | AZ21: 0 | BA21: 0 | BB21: 0 | BC21: 0 | BD21: 0 | BE21: 0 | BF21: 0 | BG21: 0 | BH21: 0
A22: Симба | B22: =SUM(C22:BH22) -> 39.9 | C22: =VLOOKUP(A22,'2025 недельный зачет'!$A:$B,2,FALSE) -> 10 | D22: =HLOOKUP(A22,'2025 все бани'!$1:$5,5,FALSE) -> 7 | E22: =HLOOKUP(A22,'2025 все бани'!$1:$5,4,FALSE) -> 3 | F22: =HLOOKUP(A22,'2025 все бани'!$1:$5,3,FALSE) -> 5 | G22: =HLOOKUP(A22,'2025 все бани'!$1:$5,2,FALSE) -> 10 | H22: 0 | I22: 0 | J22: 0 | K22: 0 | L22: 0 | M22: 0 | N22: 0 | O22: 0 | P22: 0 | Q22: 0 | R22: 0 | S22: =18/5 -> 3.6 | T22: 0 | U22: 0 | V22: 0 | W22: 0 | X22: 0 | Y22: 1 | Z22: 0 | AA22: 0 | AB22: 0 | AC22: 0 | AD22: 0 | AE22: 0 | AF22: 0 | AG22: 0 | AH22: 0 | AI22: 0 | AJ22: 0 | AK22: 0 | AL22: 0 | AM22: 0 | AN22: 0 | AO22: 0 | AP22: 0 | AQ22: 0 | AR22: 0 | AS22: 0 | AT22: 0 | AU22: 0 | AV22: 0.3 | AW22: 0 | AX22: 0 | AY22: 0 | AZ22: 0 | BA22: 0 | BB22: 0 | BC22: 0 | BD22: 0 | BE22: 0 | BF22: 0 | BG22: 0 | BH22: 0
A23: Жанат | B23: =SUM(C23:BH23) -> 39.368687 | C23: =VLOOKUP(A23,'2025 недельный зачет'!$A:$B,2,FALSE) -> 10 | D23: =HLOOKUP(A23,'2025 все бани'!$1:$5,5,FALSE) -> 6 | E23: =HLOOKUP(A23,'2025 все бани'!$1:$5,4,FALSE) -> 2 | F23: =HLOOKUP(A23,'2025 все бани'!$1:$5,3,FALSE) -> 7 | G23: =HLOOKUP(A23,'2025 все бани'!$1:$5,2,FALSE) -> 14 | H23: 0 | I23: 0 | J23: 0 | K23: 0 | L23: 0 | M23: 0 | N23: 0 | O23: 0 | P23: 0 | Q23: 0 | R23: 0 | S23: 0 | T23: 0 | U23: 0 | V23: 0 | W23: 0 | X23: =1/9 -> 0.11111111 | Y23: 0 | Z23: 0 | AA23: 0 | AB23: 0 | AC23: 0 | AD23: 0 | AE23: 0 | AF23: 0 | AG23: 0 | AH23: 0 | AI23: 0 | AJ23: 0 | AK23: =1/11 -> 0.090909091 | AL23: 0 | AM23: 0 | AN23: 0 | AO23: 0 | AP23: 0 | AQ23: =1/6 -> 0.16666667 | AR23: 0 | AS23: 0 | AT23: 0 | AU23: 0 | AV23: 0 | AW23: 0 | AX23: 0 | AY23: 0 | AZ23: 0 | BA23: 0 | BB23: 0 | BC23: 0 | BD23: 0 | BE23: 0 | BF23: 0 | BG23: 0 | BH23: 0
A24: Макс | B24: =SUM(C24:BH24) -> 31.80202 | C24: =VLOOKUP(A24,'2025 недельный зачет'!$A:$B,2,FALSE) -> 8 | D24: =HLOOKUP(A24,'2025 все бани'!$1:$5,5,FALSE) -> 6 | E24: =HLOOKUP(A24,'2025 все бани'!$1:$5,4,FALSE) -> 2 | F24: =HLOOKUP(A24,'2025 все бани'!$1:$5,3,FALSE) -> 7 | G24: =HLOOKUP(A24,'2025 все бани'!$1:$5,2,FALSE) -> 7 | H24: 0 | I24: 0 | J24: 0 | K24: 0 | L24: 0 | M24: 0 | N24: =6/10 -> 0.6 | O24: 0 | P24: 0 | Q24: 0 | R24: 0 | S24: 0 | T24: 0 | U24: 0 | V24: 0 | W24: 0 | X24: =1/9 -> 0.11111111 | Y24: 1 | Z24: 0 | AA24: 0 | AB24: 0 | AC24: 0 | AD24: 0 | AE24: 0 | AF24: 0 | AG24: 0 | AH24: 0 | AI24: 0 | AJ24: 0 | AK24: =1/11 -> 0.090909091 | AL24: 0 | AM24: 0 | AN24: 0 | AO24: 0 | AP24: 0 | AQ24: 0 | AR24: 0 | AS24: 0 | AT24: 0 | AU24: 0 | AV24: 0 | AW24: 0 | AX24: 0 | AY24: 0 | AZ24: 0 | BA24: 0 | BB24: 0 | BC24: 0 | BD24: 0 | BE24: 0 | BF24: 0 | BG24: 0 | BH24: 0
A25: Виталик | B25: =SUM(C25:BH25) -> 23.411111 | C25: =VLOOKUP(A25,'2025 недельный зачет'!$A:$B,2,FALSE) -> 6 | D25: =HLOOKUP(A25,'2025 все бани'!$1:$5,5,FALSE) -> 5 | E25: =HLOOKUP(A25,'2025 все бани'!$1:$5,4,FALSE) -> 1 | F25: =HLOOKUP(A25,'2025 все бани'!$1:$5,3,FALSE) -> 5 | G25: =HLOOKUP(A25,'2025 все бани'!$1:$5,2,FALSE) -> 6 | H25: 0 | I25: 0 | J25: 0 | K25: 0 | L25: 0 | M25: 0 | N25: 0 | O25: 0 | P25: 0 | Q25: 0 | R25: 0 | S25: 0 | T25: 0 | U25: 0 | V25: 0 | W25: 0 | X25: =1/9 -> 0.11111111 | Y25: 0 | Z25: 0 | AA25: 0 | AB25: 0 | AC25: 0 | AD25: 0 | AE25: 0 | AF25: 0 | AG25: 0 | AH25: 0 | AI25: 0 | AJ25: 0 | AK25: 0 | AL25: 0 | AM25: 0 | AN25: 0 | AO25: 0 | AP25: 0 | AQ25: 0 | AR25: 0 | AS25: 0 | AT25: 0 | AU25: 0 | AV25: 0.3 | AW25: 0 | AX25: 0 | AY25: 0 | AZ25: 0 | BA25: 0 | BB25: 0 | BC25: 0 | BD25: 0 | BE25: 0 | BF25: 0 | BG25: 0 | BH25: 0
A26: Дёс | B26: =SUM(C26:BH26) -> 23.090909 | C26: =VLOOKUP(A26,'2025 недельный зачет'!$A:$B,2,FALSE) -> 5 | D26: =HLOOKUP(A26,'2025 все бани'!$1:$5,5,FALSE) -> 5 | E26: =HLOOKUP(A26,'2025 все бани'!$1:$5,4,FALSE) -> 3 | F26: =HLOOKUP(A26,'2025 все бани'!$1:$5,3,FALSE) -> 3 | G26: =HLOOKUP(A26,'2025 все бани'!$1:$5,2,FALSE) -> 6 | H26: 0 | I26: 0 | J26: 0 | K26: 0 | L26: 0 | M26: 0 | N26: 0 | O26: 0 | P26: 0 | Q26: 0 | R26: 0 | S26: 0 | T26: 0 | U26: 0 | V26: 0 | W26: 0 | X26: 0 | Y26: 1 | Z26: 0 | AA26: 0 | AB26: 0 | AC26: 0 | AD26: 0 | AE26: 0 | AF26: 0 | AG26: 0 | AH26: 0 | AI26: 0 | AJ26: 0 | AK26: 0 | AL26: 0 | AM26: 0 | AN26: 0 | AO26: 0 | AP26: 0 | AQ26: 0 | AR26: 0 | AS26: 0 | AT26: 0 | AU26: 0 | AV26: 0 | AW26: 0 | AX26: 0 | AY26: 0 | AZ26: 0.090909091 | BA26: 0 | BB26: 0 | BC26: 0 | BD26: 0 | BE26: 0 | BF26: 0 | BG26: 0 | BH26: 0
A27: Костян | B27: =SUM(C27:BH27) -> 22.80202 | C27: =VLOOKUP(A27,'2025 недельный зачет'!$A:$B,2,FALSE) -> 5 | D27: =HLOOKUP(A27,'2025 все бани'!$1:$5,5,FALSE) -> 4 | E27: =HLOOKUP(A27,'2025 все бани'!$1:$5,4,FALSE) -> 1 | F27: =HLOOKUP(A27,'2025 все бани'!$1:$5,3,FALSE) -> 5 | G27: =HLOOKUP(A27,'2025 все бани'!$1:$5,2,FALSE) -> 7 | H27: 0 | I27: 0 | J27: 0 | K27: 0 | L27: 0 | M27: 0 | N27: =6/10 -> 0.6 | O27: 0 | P27: 0 | Q27: 0 | R27: 0 | S27: 0 | T27: 0 | U27: 0 | V27: 0 | W27: 0 | X27: =1/9 -> 0.11111111 | Y27: 0 | Z27: 0 | AA27: 0 | AB27: 0 | AC27: 0 | AD27: 0 | AE27: 0 | AF27: 0 | AG27: 0 | AH27: 0 | AI27: 0 | AJ27: 0 | AK27: =1/11 -> 0.090909091 | AL27: 0 | AM27: 0 | AN27: 0 | AO27: 0 | AP27: 0 | AQ27: 0 | AR27: 0 | AS27: 0 | AT27: 0 | AU27: 0 | AV27: 0 | AW27: 0 | AX27: 0 | AY27: 0 | AZ27: 0 | BA27: 0 | BB27: 0 | BC27: 0 | BD27: 0 | BE27: 0 | BF27: 0 | BG27: 0 | BH27: 0
A28: Саня С | B28: =SUM(C28:BH28) -> 18.20202 | C28: =VLOOKUP(A28,'2025 недельный зачет'!$A:$B,2,FALSE) -> 4 | D28: =HLOOKUP(A28,'2025 все бани'!$1:$5,5,FALSE) -> 3 | E28: =HLOOKUP(A28,'2025 все бани'!$1:$5,4,FALSE) -> 1 | F28: =HLOOKUP(A28,'2025 все бани'!$1:$5,3,FALSE) -> 4 | G28: =HLOOKUP(A28,'2025 все бани'!$1:$5,2,FALSE) -> 6 | H28: 0 | I28: 0 | J28: 0 | K28: 0 | L28: 0 | M28: 0 | N28: 0 | O28: 0 | P28: 0 | Q28: 0 | R28: 0 | S28: 0 | T28: 0 | U28: 0 | V28: 0 | W28: 0 | X28: =1/9 -> 0.11111111 | Y28: 0 | Z28: 0 | AA28: 0 | AB28: 0 | AC28: 0 | AD28: 0 | AE28: 0 | AF28: 0 | AG28: 0 | AH28: 0 | AI28: 0 | AJ28: 0 | AK28: =1/11 -> 0.090909091 | AL28: 0 | AM28: 0 | AN28: 0 | AO28: 0 | AP28: 0 | AQ28: 0 | AR28: 0 | AS28: 0 | AT28: 0 | AU28: 0 | AV28: 0 | AW28: 0 | AX28: 0 | AY28: 0 | AZ28: 0 | BA28: 0 | BB28: 0 | BC28: 0 | BD28: 0 | BE28: 0 | BF28: 0 | BG28: 0 | BH28: 0
A29: Толмач | B29: =SUM(C29:BH29) -> 17.024242 | C29: =VLOOKUP(A29,'2025 недельный зачет'!$A:$B,2,FALSE) -> 4 | D29: =HLOOKUP(A29,'2025 все бани'!$1:$5,5,FALSE) -> 4 | E29: =HLOOKUP(A29,'2025 все бани'!$1:$5,4,FALSE) -> 4 | F29: =HLOOKUP(A29,'2025 все бани'!$1:$5,3,FALSE) -> 1 | G29: =HLOOKUP(A29,'2025 все бани'!$1:$5,2,FALSE) -> 0 | H29: 0 | I29: 0 | J29: 0 | K29: =3/5 -> 0.6 | L29: 0 | M29: 0 | N29: 0 | O29: 0 | P29: 0 | Q29: 0 | R29: 0 | S29: 0 | T29: 0 | U29: 0 | V29: 0 | W29: 0 | X29: 0 | Y29: 0 | Z29: 0 | AA29: 0 | AB29: 0 | AC29: 0 | AD29: 0 | AE29: 0 | AF29: 0 | AG29: 0 | AH29: 0 | AI29: 0 | AJ29: 0 | AK29: 0 | AL29: 0 | AM29: 0 | AN29: 0 | AO29: 0 | AP29: 0 | AQ29: 0 | AR29: 0 | AS29: 0 | AT29: 0 | AU29: 0 | AV29: 0 | AW29: 0 | AX29: 0 | AY29: 0 | AZ29: 3.3333333 | BA29: 0 | BB29: 0 | BC29: 0 | BD29: 0 | BE29: =1/11 -> 0.090909091 | BF29: 0 | BG29: 0 | BH29: 0
A30: Вадик | B30: =SUM(C30:BH30) -> 17 | C30: =VLOOKUP(A30,'2025 недельный зачет'!$A:$B,2,FALSE) -> 4 | D30: =HLOOKUP(A30,'2025 все бани'!$1:$5,5,FALSE) -> 3 | E30: =HLOOKUP(A30,'2025 все бани'!$1:$5,4,FALSE) -> 0 | F30: =HLOOKUP(A30,'2025 все бани'!$1:$5,3,FALSE) -> 4 | G30: =HLOOKUP(A30,'2025 все бани'!$1:$5,2,FALSE) -> 6 | H30: 0 | I30: 0 | J30: 0 | K30: 0 | L30: 0 | M30: 0 | N30: 0 | O30: 0 | P30: 0 | Q30: 0 | R30: 0 | S30: 0 | T30: 0 | U30: 0 | V30: 0 | W30: 0 | X30: 0 | Y30: 0 | Z30: 0 | AA30: 0 | AB30: 0 | AC30: 0 | AD30: 0 | AE30: 0 | AF30: 0 | AG30: 0 | AH30: 0 | AI30: 0 | AJ30: 0 | AK30: 0 | AL30: 0 | AM30: 0 | AN30: 0 | AO30: 0 | AP30: 0 | AQ30: 0 | AR30: 0 | AS30: 0 | AT30: 0 | AU30: 0 | AV30: 0 | AW30: 0 | AX30: 0 | AY30: 0 | AZ30: 0 | BA30: 0 | BB30: 0 | BC30: 0 | BD30: 0 | BE30: 0 | BF30: 0 | BG30: 0 | BH30: 0
